2024-07-24 13:20:40,800 ERROR django.request Internal Server Error: /api/v1/reservations/multiple_rooms_check_in
Traceback (most recent call last):
  File "/home/kali/.local/lib/python3.11/site-packages/django/core/handlers/exception.py", line 55, in inner
    response = get_response(request)
               ^^^^^^^^^^^^^^^^^^^^^
  File "/home/kali/.local/lib/python3.11/site-packages/django/core/handlers/base.py", line 197, in _get_response
    response = wrapped_callback(request, *callback_args, **callback_kwargs)
               ^^^^^^^^^^^^^^^^^^^^^^^^^^^^^^^^^^^^^^^^^^^^^^^^^^^^^^^^^^^^
  File "/home/kali/.local/lib/python3.11/site-packages/django/views/decorators/csrf.py", line 65, in _view_wrapper
    return view_func(request, *args, **kwargs)
           ^^^^^^^^^^^^^^^^^^^^^^^^^^^^^^^^^^^
  File "/home/kali/.local/lib/python3.11/site-packages/django/views/generic/base.py", line 104, in view
    return self.dispatch(request, *args, **kwargs)
           ^^^^^^^^^^^^^^^^^^^^^^^^^^^^^^^^^^^^^^^
  File "/home/kali/.local/lib/python3.11/site-packages/rest_framework/views.py", line 509, in dispatch
    response = self.handle_exception(exc)
               ^^^^^^^^^^^^^^^^^^^^^^^^^^
  File "/home/kali/.local/lib/python3.11/site-packages/rest_framework/views.py", line 469, in handle_exception
    self.raise_uncaught_exception(exc)
  File "/home/kali/.local/lib/python3.11/site-packages/rest_framework/views.py", line 480, in raise_uncaught_exception
    raise exc
  File "/home/kali/.local/lib/python3.11/site-packages/rest_framework/views.py", line 506, in dispatch
    response = handler(request, *args, **kwargs)
               ^^^^^^^^^^^^^^^^^^^^^^^^^^^^^^^^^
  File "/home/kali/Desktop/ruumready/hotel_manager/reservations/views.py", line 298, in patch
    if booking.check_in_time:
       ^^^^^^^^^^^^^^^^^^^^^
AttributeError: 'Booking' object has no attribute 'check_in_time'
2024-07-24 13:20:40,802 ERROR django.server "PATCH /api/v1/reservations/multiple_rooms_check_in HTTP/1.1" 500 106782
2024-07-24 13:20:40,802 ERROR django.server "PATCH /api/v1/reservations/multiple_rooms_check_in HTTP/1.1" 500 106782
2024-07-24 13:21:49,599 INFO django.utils.autoreload /home/kali/Desktop/ruumready/hotel_manager/reservations/views.py changed, reloading.
2024-07-24 13:21:49,599 INFO django.utils.autoreload /home/kali/Desktop/ruumready/hotel_manager/reservations/views.py changed, reloading.
2024-07-24 13:21:51,152 INFO django.utils.autoreload Watching for file changes with StatReloader
2024-07-24 13:21:51,152 INFO django.utils.autoreload Watching for file changes with StatReloader
2024-07-24 13:21:52,675 INFO django.utils.autoreload /home/kali/Desktop/ruumready/hotel_manager/reservations/views.py changed, reloading.
2024-07-24 13:21:52,675 INFO django.utils.autoreload /home/kali/Desktop/ruumready/hotel_manager/reservations/views.py changed, reloading.
2024-07-24 13:21:53,710 INFO django.utils.autoreload Watching for file changes with StatReloader
2024-07-24 13:21:53,710 INFO django.utils.autoreload Watching for file changes with StatReloader
2024-07-24 13:22:07,257 INFO django.server "PATCH /api/v1/reservations/multiple_rooms_check_in HTTP/1.1" 200 148
2024-07-24 13:22:07,257 INFO django.server "PATCH /api/v1/reservations/multiple_rooms_check_in HTTP/1.1" 200 148
2024-07-24 13:22:23,330 INFO django.server "PATCH /api/v1/reservations/multiple_rooms_check_in HTTP/1.1" 200 150
2024-07-24 13:22:23,330 INFO django.server "PATCH /api/v1/reservations/multiple_rooms_check_in HTTP/1.1" 200 150
2024-07-24 13:22:36,210 INFO django.server "PATCH /api/v1/reservations/multiple_rooms_check_in HTTP/1.1" 200 150
2024-07-24 13:22:36,210 INFO django.server "PATCH /api/v1/reservations/multiple_rooms_check_in HTTP/1.1" 200 150
2024-07-24 13:23:12,433 WARNING django.request Bad Request: /api/v1/reservations/book-room
2024-07-24 13:23:12,433 WARNING django.request Bad Request: /api/v1/reservations/book-room
2024-07-24 13:23:12,434 WARNING django.server "POST /api/v1/reservations/book-room HTTP/1.1" 400 74
2024-07-24 13:23:12,434 WARNING django.server "POST /api/v1/reservations/book-room HTTP/1.1" 400 74
2024-07-24 13:23:49,990 WARNING django.request Bad Request: /api/v1/reservations/check-user-out
2024-07-24 13:23:49,990 WARNING django.request Bad Request: /api/v1/reservations/check-user-out
2024-07-24 13:23:49,993 WARNING django.server "PATCH /api/v1/reservations/check-user-out HTTP/1.1" 400 74
2024-07-24 13:23:49,993 WARNING django.server "PATCH /api/v1/reservations/check-user-out HTTP/1.1" 400 74
2024-07-24 13:24:20,617 INFO django.server "PATCH /api/v1/reservations/multiple_rooms_check_in HTTP/1.1" 200 150
2024-07-24 13:24:20,617 INFO django.server "PATCH /api/v1/reservations/multiple_rooms_check_in HTTP/1.1" 200 150
2024-07-24 13:25:12,512 INFO django.server "PATCH /api/v1/reservations/multiple_rooms_check_in HTTP/1.1" 200 150
2024-07-24 13:25:12,512 INFO django.server "PATCH /api/v1/reservations/multiple_rooms_check_in HTTP/1.1" 200 150
2024-07-24 13:28:26,929 INFO django.utils.autoreload /home/kali/Desktop/ruumready/hotel_manager/reservations/views.py changed, reloading.
2024-07-24 13:28:26,929 INFO django.utils.autoreload /home/kali/Desktop/ruumready/hotel_manager/reservations/views.py changed, reloading.
2024-07-24 13:28:28,574 INFO django.utils.autoreload Watching for file changes with StatReloader
2024-07-24 13:28:28,574 INFO django.utils.autoreload Watching for file changes with StatReloader
2024-07-24 13:30:18,502 ERROR django.request Internal Server Error: /api/v1/reservations/multiple_rooms_check_in
Traceback (most recent call last):
  File "/home/kali/.local/lib/python3.11/site-packages/django/core/handlers/exception.py", line 55, in inner
    response = get_response(request)
               ^^^^^^^^^^^^^^^^^^^^^
  File "/home/kali/.local/lib/python3.11/site-packages/django/core/handlers/base.py", line 197, in _get_response
    response = wrapped_callback(request, *callback_args, **callback_kwargs)
               ^^^^^^^^^^^^^^^^^^^^^^^^^^^^^^^^^^^^^^^^^^^^^^^^^^^^^^^^^^^^
  File "/home/kali/.local/lib/python3.11/site-packages/django/views/decorators/csrf.py", line 65, in _view_wrapper
    return view_func(request, *args, **kwargs)
           ^^^^^^^^^^^^^^^^^^^^^^^^^^^^^^^^^^^
  File "/home/kali/.local/lib/python3.11/site-packages/django/views/generic/base.py", line 104, in view
    return self.dispatch(request, *args, **kwargs)
           ^^^^^^^^^^^^^^^^^^^^^^^^^^^^^^^^^^^^^^^
  File "/home/kali/.local/lib/python3.11/site-packages/rest_framework/views.py", line 509, in dispatch
    response = self.handle_exception(exc)
               ^^^^^^^^^^^^^^^^^^^^^^^^^^
  File "/home/kali/.local/lib/python3.11/site-packages/rest_framework/views.py", line 469, in handle_exception
    self.raise_uncaught_exception(exc)
  File "/home/kali/.local/lib/python3.11/site-packages/rest_framework/views.py", line 480, in raise_uncaught_exception
    raise exc
  File "/home/kali/.local/lib/python3.11/site-packages/rest_framework/views.py", line 506, in dispatch
    response = handler(request, *args, **kwargs)
               ^^^^^^^^^^^^^^^^^^^^^^^^^^^^^^^^^
  File "/home/kali/Desktop/ruumready/hotel_manager/reservations/views.py", line 298, in patch
    if booking.check_in_time:
       ^^^^^^^^^^^^^^^^^^^^^
AttributeError: 'Booking' object has no attribute 'check_in_time'
2024-07-24 13:30:18,502 ERROR django.request Internal Server Error: /api/v1/reservations/multiple_rooms_check_in
Traceback (most recent call last):
  File "/home/kali/.local/lib/python3.11/site-packages/django/core/handlers/exception.py", line 55, in inner
    response = get_response(request)
               ^^^^^^^^^^^^^^^^^^^^^
  File "/home/kali/.local/lib/python3.11/site-packages/django/core/handlers/base.py", line 197, in _get_response
    response = wrapped_callback(request, *callback_args, **callback_kwargs)
               ^^^^^^^^^^^^^^^^^^^^^^^^^^^^^^^^^^^^^^^^^^^^^^^^^^^^^^^^^^^^
  File "/home/kali/.local/lib/python3.11/site-packages/django/views/decorators/csrf.py", line 65, in _view_wrapper
    return view_func(request, *args, **kwargs)
           ^^^^^^^^^^^^^^^^^^^^^^^^^^^^^^^^^^^
  File "/home/kali/.local/lib/python3.11/site-packages/django/views/generic/base.py", line 104, in view
    return self.dispatch(request, *args, **kwargs)
           ^^^^^^^^^^^^^^^^^^^^^^^^^^^^^^^^^^^^^^^
  File "/home/kali/.local/lib/python3.11/site-packages/rest_framework/views.py", line 509, in dispatch
    response = self.handle_exception(exc)
               ^^^^^^^^^^^^^^^^^^^^^^^^^^
  File "/home/kali/.local/lib/python3.11/site-packages/rest_framework/views.py", line 469, in handle_exception
    self.raise_uncaught_exception(exc)
  File "/home/kali/.local/lib/python3.11/site-packages/rest_framework/views.py", line 480, in raise_uncaught_exception
    raise exc
  File "/home/kali/.local/lib/python3.11/site-packages/rest_framework/views.py", line 506, in dispatch
    response = handler(request, *args, **kwargs)
               ^^^^^^^^^^^^^^^^^^^^^^^^^^^^^^^^^
  File "/home/kali/Desktop/ruumready/hotel_manager/reservations/views.py", line 298, in patch
    if booking.check_in_time:
       ^^^^^^^^^^^^^^^^^^^^^
AttributeError: 'Booking' object has no attribute 'check_in_time'
2024-07-24 13:30:18,504 ERROR django.server "PATCH /api/v1/reservations/multiple_rooms_check_in HTTP/1.1" 500 106782
2024-07-24 13:30:18,504 ERROR django.server "PATCH /api/v1/reservations/multiple_rooms_check_in HTTP/1.1" 500 106782
2024-07-24 13:31:12,929 INFO django.utils.autoreload /home/kali/Desktop/ruumready/hotel_manager/reservations/views.py changed, reloading.
2024-07-24 13:31:12,929 INFO django.utils.autoreload /home/kali/Desktop/ruumready/hotel_manager/reservations/views.py changed, reloading.
2024-07-24 13:31:14,630 INFO django.utils.autoreload Watching for file changes with StatReloader
2024-07-24 13:31:14,630 INFO django.utils.autoreload Watching for file changes with StatReloader
2024-07-24 13:31:37,108 WARNING django.request Bad Request: /api/v1/reservations/multiple_rooms_check_in
2024-07-24 13:31:37,108 WARNING django.request Bad Request: /api/v1/reservations/multiple_rooms_check_in
2024-07-24 13:31:37,111 WARNING django.server "PATCH /api/v1/reservations/multiple_rooms_check_in HTTP/1.1" 400 132
2024-07-24 13:31:37,111 WARNING django.server "PATCH /api/v1/reservations/multiple_rooms_check_in HTTP/1.1" 400 132
2024-07-24 13:32:10,061 WARNING django.request Bad Request: /api/v1/reservations/multiple_rooms_check_in
2024-07-24 13:32:10,061 WARNING django.request Bad Request: /api/v1/reservations/multiple_rooms_check_in
2024-07-24 13:32:10,064 WARNING django.server "PATCH /api/v1/reservations/multiple_rooms_check_in HTTP/1.1" 400 132
2024-07-24 13:32:10,064 WARNING django.server "PATCH /api/v1/reservations/multiple_rooms_check_in HTTP/1.1" 400 132
2024-07-24 13:34:54,167 INFO django.utils.autoreload /home/kali/Desktop/ruumready/hotel_manager/reservations/views.py changed, reloading.
2024-07-24 13:34:54,167 INFO django.utils.autoreload /home/kali/Desktop/ruumready/hotel_manager/reservations/views.py changed, reloading.
2024-07-24 13:34:56,443 INFO django.utils.autoreload Watching for file changes with StatReloader
2024-07-24 13:34:56,443 INFO django.utils.autoreload Watching for file changes with StatReloader
2024-07-24 13:34:58,956 INFO django.utils.autoreload /home/kali/Desktop/ruumready/hotel_manager/reservations/views.py changed, reloading.
2024-07-24 13:34:58,956 INFO django.utils.autoreload /home/kali/Desktop/ruumready/hotel_manager/reservations/views.py changed, reloading.
2024-07-24 13:35:00,424 INFO django.utils.autoreload Watching for file changes with StatReloader
2024-07-24 13:35:00,424 INFO django.utils.autoreload Watching for file changes with StatReloader
2024-07-24 13:35:10,112 WARNING django.request Bad Request: /api/v1/reservations/multiple_rooms_check_in
2024-07-24 13:35:10,112 WARNING django.request Bad Request: /api/v1/reservations/multiple_rooms_check_in
2024-07-24 13:35:10,114 WARNING django.server "PATCH /api/v1/reservations/multiple_rooms_check_in HTTP/1.1" 400 132
2024-07-24 13:35:10,114 WARNING django.server "PATCH /api/v1/reservations/multiple_rooms_check_in HTTP/1.1" 400 132
2024-07-24 13:35:29,242 WARNING django.request Bad Request: /api/v1/reservations/check-user-out
2024-07-24 13:35:29,242 WARNING django.request Bad Request: /api/v1/reservations/check-user-out
2024-07-24 13:35:29,247 WARNING django.server "PATCH /api/v1/reservations/check-user-out HTTP/1.1" 400 74
2024-07-24 13:35:29,247 WARNING django.server "PATCH /api/v1/reservations/check-user-out HTTP/1.1" 400 74
2024-07-24 13:36:02,403 WARNING django.request Bad Request: /api/v1/reservations/check-user-out
2024-07-24 13:36:02,403 WARNING django.request Bad Request: /api/v1/reservations/check-user-out
2024-07-24 13:36:02,407 WARNING django.server "PATCH /api/v1/reservations/check-user-out HTTP/1.1" 400 74
2024-07-24 13:36:02,407 WARNING django.server "PATCH /api/v1/reservations/check-user-out HTTP/1.1" 400 74
2024-07-24 13:36:11,325 WARNING django.request Bad Request: /api/v1/reservations/check-user-out
2024-07-24 13:36:11,325 WARNING django.request Bad Request: /api/v1/reservations/check-user-out
2024-07-24 13:36:11,330 WARNING django.server "PATCH /api/v1/reservations/check-user-out HTTP/1.1" 400 74
2024-07-24 13:36:11,330 WARNING django.server "PATCH /api/v1/reservations/check-user-out HTTP/1.1" 400 74
2024-07-24 13:36:31,192 WARNING django.request Bad Request: /api/v1/reservations/checkout
2024-07-24 13:36:31,192 WARNING django.request Bad Request: /api/v1/reservations/checkout
2024-07-24 13:36:31,194 WARNING django.server "PATCH /api/v1/reservations/checkout HTTP/1.1" 400 72
2024-07-24 13:36:31,194 WARNING django.server "PATCH /api/v1/reservations/checkout HTTP/1.1" 400 72
2024-07-24 13:36:49,912 INFO django.server "PATCH /api/v1/reservations/checkout HTTP/1.1" 200 47
2024-07-24 13:36:49,912 INFO django.server "PATCH /api/v1/reservations/checkout HTTP/1.1" 200 47
2024-07-24 13:38:00,137 ERROR django.request Internal Server Error: /api/v1/reservations/checkout
Traceback (most recent call last):
  File "/home/kali/.local/lib/python3.11/site-packages/django/core/handlers/exception.py", line 55, in inner
    response = get_response(request)
               ^^^^^^^^^^^^^^^^^^^^^
  File "/home/kali/.local/lib/python3.11/site-packages/django/core/handlers/base.py", line 197, in _get_response
    response = wrapped_callback(request, *callback_args, **callback_kwargs)
               ^^^^^^^^^^^^^^^^^^^^^^^^^^^^^^^^^^^^^^^^^^^^^^^^^^^^^^^^^^^^
  File "/home/kali/.local/lib/python3.11/site-packages/django/views/decorators/csrf.py", line 65, in _view_wrapper
    return view_func(request, *args, **kwargs)
           ^^^^^^^^^^^^^^^^^^^^^^^^^^^^^^^^^^^
  File "/home/kali/.local/lib/python3.11/site-packages/django/views/generic/base.py", line 104, in view
    return self.dispatch(request, *args, **kwargs)
           ^^^^^^^^^^^^^^^^^^^^^^^^^^^^^^^^^^^^^^^
  File "/home/kali/.local/lib/python3.11/site-packages/rest_framework/views.py", line 509, in dispatch
    response = self.handle_exception(exc)
               ^^^^^^^^^^^^^^^^^^^^^^^^^^
  File "/home/kali/.local/lib/python3.11/site-packages/rest_framework/views.py", line 469, in handle_exception
    self.raise_uncaught_exception(exc)
  File "/home/kali/.local/lib/python3.11/site-packages/rest_framework/views.py", line 480, in raise_uncaught_exception
    raise exc
  File "/home/kali/.local/lib/python3.11/site-packages/rest_framework/views.py", line 506, in dispatch
    response = handler(request, *args, **kwargs)
               ^^^^^^^^^^^^^^^^^^^^^^^^^^^^^^^^^
  File "/home/kali/Desktop/ruumready/hotel_manager/reservations/views.py", line 426, in patch
    serializer.update(validated_data=request.data)
  File "/home/kali/Desktop/ruumready/hotel_manager/reservations/serializers.py", line 246, in update
    model = Booking.objects.check_user_out_ext(
            ^^^^^^^^^^^^^^^^^^^^^^^^^^^^^^^^^^^
  File "/home/kali/Desktop/ruumready/hotel_manager/reservations/managers.py", line 309, in check_user_out_ext
    booking_record = Booking.objects.filter(**{'id': record.booking.id})
                                                     ^^^^^^^^^^^^^^^^^
AttributeError: 'NoneType' object has no attribute 'id'
2024-07-24 13:38:00,137 ERROR django.request Internal Server Error: /api/v1/reservations/checkout
Traceback (most recent call last):
  File "/home/kali/.local/lib/python3.11/site-packages/django/core/handlers/exception.py", line 55, in inner
    response = get_response(request)
               ^^^^^^^^^^^^^^^^^^^^^
  File "/home/kali/.local/lib/python3.11/site-packages/django/core/handlers/base.py", line 197, in _get_response
    response = wrapped_callback(request, *callback_args, **callback_kwargs)
               ^^^^^^^^^^^^^^^^^^^^^^^^^^^^^^^^^^^^^^^^^^^^^^^^^^^^^^^^^^^^
  File "/home/kali/.local/lib/python3.11/site-packages/django/views/decorators/csrf.py", line 65, in _view_wrapper
    return view_func(request, *args, **kwargs)
           ^^^^^^^^^^^^^^^^^^^^^^^^^^^^^^^^^^^
  File "/home/kali/.local/lib/python3.11/site-packages/django/views/generic/base.py", line 104, in view
    return self.dispatch(request, *args, **kwargs)
           ^^^^^^^^^^^^^^^^^^^^^^^^^^^^^^^^^^^^^^^
  File "/home/kali/.local/lib/python3.11/site-packages/rest_framework/views.py", line 509, in dispatch
    response = self.handle_exception(exc)
               ^^^^^^^^^^^^^^^^^^^^^^^^^^
  File "/home/kali/.local/lib/python3.11/site-packages/rest_framework/views.py", line 469, in handle_exception
    self.raise_uncaught_exception(exc)
  File "/home/kali/.local/lib/python3.11/site-packages/rest_framework/views.py", line 480, in raise_uncaught_exception
    raise exc
  File "/home/kali/.local/lib/python3.11/site-packages/rest_framework/views.py", line 506, in dispatch
    response = handler(request, *args, **kwargs)
               ^^^^^^^^^^^^^^^^^^^^^^^^^^^^^^^^^
  File "/home/kali/Desktop/ruumready/hotel_manager/reservations/views.py", line 426, in patch
    serializer.update(validated_data=request.data)
  File "/home/kali/Desktop/ruumready/hotel_manager/reservations/serializers.py", line 246, in update
    model = Booking.objects.check_user_out_ext(
            ^^^^^^^^^^^^^^^^^^^^^^^^^^^^^^^^^^^
  File "/home/kali/Desktop/ruumready/hotel_manager/reservations/managers.py", line 309, in check_user_out_ext
    booking_record = Booking.objects.filter(**{'id': record.booking.id})
                                                     ^^^^^^^^^^^^^^^^^
AttributeError: 'NoneType' object has no attribute 'id'
2024-07-24 13:38:00,141 ERROR django.server "PATCH /api/v1/reservations/checkout HTTP/1.1" 500 112703
2024-07-24 13:38:00,141 ERROR django.server "PATCH /api/v1/reservations/checkout HTTP/1.1" 500 112703
2024-07-24 13:41:29,845 INFO django.utils.autoreload /home/kali/Desktop/ruumready/hotel_manager/reservations/managers.py changed, reloading.
2024-07-24 13:41:29,845 INFO django.utils.autoreload /home/kali/Desktop/ruumready/hotel_manager/reservations/managers.py changed, reloading.
2024-07-24 13:41:32,617 INFO django.utils.autoreload Watching for file changes with StatReloader
2024-07-24 13:41:32,617 INFO django.utils.autoreload Watching for file changes with StatReloader
2024-07-24 13:41:37,011 INFO django.utils.autoreload /home/kali/Desktop/ruumready/hotel_manager/reservations/managers.py changed, reloading.
2024-07-24 13:41:37,011 INFO django.utils.autoreload /home/kali/Desktop/ruumready/hotel_manager/reservations/managers.py changed, reloading.
2024-07-24 13:41:39,592 INFO django.utils.autoreload Watching for file changes with StatReloader
2024-07-24 13:41:39,592 INFO django.utils.autoreload Watching for file changes with StatReloader
2024-07-24 14:22:44,586 ERROR django.request Internal Server Error: /api/v1/reservations/checkout
Traceback (most recent call last):
  File "/home/kali/.local/lib/python3.11/site-packages/django/core/handlers/exception.py", line 55, in inner
    response = get_response(request)
               ^^^^^^^^^^^^^^^^^^^^^
  File "/home/kali/.local/lib/python3.11/site-packages/django/core/handlers/base.py", line 197, in _get_response
    response = wrapped_callback(request, *callback_args, **callback_kwargs)
               ^^^^^^^^^^^^^^^^^^^^^^^^^^^^^^^^^^^^^^^^^^^^^^^^^^^^^^^^^^^^
  File "/home/kali/.local/lib/python3.11/site-packages/django/views/decorators/csrf.py", line 65, in _view_wrapper
    return view_func(request, *args, **kwargs)
           ^^^^^^^^^^^^^^^^^^^^^^^^^^^^^^^^^^^
  File "/home/kali/.local/lib/python3.11/site-packages/django/views/generic/base.py", line 104, in view
    return self.dispatch(request, *args, **kwargs)
           ^^^^^^^^^^^^^^^^^^^^^^^^^^^^^^^^^^^^^^^
  File "/home/kali/.local/lib/python3.11/site-packages/rest_framework/views.py", line 509, in dispatch
    response = self.handle_exception(exc)
               ^^^^^^^^^^^^^^^^^^^^^^^^^^
  File "/home/kali/.local/lib/python3.11/site-packages/rest_framework/views.py", line 469, in handle_exception
    self.raise_uncaught_exception(exc)
  File "/home/kali/.local/lib/python3.11/site-packages/rest_framework/views.py", line 480, in raise_uncaught_exception
    raise exc
  File "/home/kali/.local/lib/python3.11/site-packages/rest_framework/views.py", line 506, in dispatch
    response = handler(request, *args, **kwargs)
               ^^^^^^^^^^^^^^^^^^^^^^^^^^^^^^^^^
  File "/home/kali/Desktop/ruumready/hotel_manager/reservations/views.py", line 426, in patch
    serializer.update(validated_data=request.data)
  File "/home/kali/Desktop/ruumready/hotel_manager/reservations/serializers.py", line 246, in update
    model = Booking.objects.check_user_out_ext(
            ^^^^^^^^^^^^^^^^^^^^^^^^^^^^^^^^^^^
  File "/home/kali/Desktop/ruumready/hotel_manager/reservations/managers.py", line 302, in check_user_out_ext
    booking_record = Booking.objects.filter(**{'id': record.booking.id})
                                                     ^^^^^^^^^^^^^^^^^
AttributeError: 'NoneType' object has no attribute 'id'
2024-07-24 14:22:44,586 ERROR django.request Internal Server Error: /api/v1/reservations/checkout
Traceback (most recent call last):
  File "/home/kali/.local/lib/python3.11/site-packages/django/core/handlers/exception.py", line 55, in inner
    response = get_response(request)
               ^^^^^^^^^^^^^^^^^^^^^
  File "/home/kali/.local/lib/python3.11/site-packages/django/core/handlers/base.py", line 197, in _get_response
    response = wrapped_callback(request, *callback_args, **callback_kwargs)
               ^^^^^^^^^^^^^^^^^^^^^^^^^^^^^^^^^^^^^^^^^^^^^^^^^^^^^^^^^^^^
  File "/home/kali/.local/lib/python3.11/site-packages/django/views/decorators/csrf.py", line 65, in _view_wrapper
    return view_func(request, *args, **kwargs)
           ^^^^^^^^^^^^^^^^^^^^^^^^^^^^^^^^^^^
  File "/home/kali/.local/lib/python3.11/site-packages/django/views/generic/base.py", line 104, in view
    return self.dispatch(request, *args, **kwargs)
           ^^^^^^^^^^^^^^^^^^^^^^^^^^^^^^^^^^^^^^^
  File "/home/kali/.local/lib/python3.11/site-packages/rest_framework/views.py", line 509, in dispatch
    response = self.handle_exception(exc)
               ^^^^^^^^^^^^^^^^^^^^^^^^^^
  File "/home/kali/.local/lib/python3.11/site-packages/rest_framework/views.py", line 469, in handle_exception
    self.raise_uncaught_exception(exc)
  File "/home/kali/.local/lib/python3.11/site-packages/rest_framework/views.py", line 480, in raise_uncaught_exception
    raise exc
  File "/home/kali/.local/lib/python3.11/site-packages/rest_framework/views.py", line 506, in dispatch
    response = handler(request, *args, **kwargs)
               ^^^^^^^^^^^^^^^^^^^^^^^^^^^^^^^^^
  File "/home/kali/Desktop/ruumready/hotel_manager/reservations/views.py", line 426, in patch
    serializer.update(validated_data=request.data)
  File "/home/kali/Desktop/ruumready/hotel_manager/reservations/serializers.py", line 246, in update
    model = Booking.objects.check_user_out_ext(
            ^^^^^^^^^^^^^^^^^^^^^^^^^^^^^^^^^^^
  File "/home/kali/Desktop/ruumready/hotel_manager/reservations/managers.py", line 302, in check_user_out_ext
    booking_record = Booking.objects.filter(**{'id': record.booking.id})
                                                     ^^^^^^^^^^^^^^^^^
AttributeError: 'NoneType' object has no attribute 'id'
2024-07-24 14:22:44,588 ERROR django.server "PATCH /api/v1/reservations/checkout HTTP/1.1" 500 112703
2024-07-24 14:22:44,588 ERROR django.server "PATCH /api/v1/reservations/checkout HTTP/1.1" 500 112703
2024-07-24 14:25:03,166 INFO django.server "GET /api/v1/reservations/user-booking-history/ecab5863-6124-46a9-ae0c-4a132a3bd1b5 HTTP/1.1" 200 730
2024-07-24 14:25:03,166 INFO django.server "GET /api/v1/reservations/user-booking-history/ecab5863-6124-46a9-ae0c-4a132a3bd1b5 HTTP/1.1" 200 730
2024-07-24 14:25:12,208 INFO django.server "GET /api/v1/accounts/users HTTP/1.1" 200 466
2024-07-24 14:25:12,208 INFO django.server "GET /api/v1/accounts/users HTTP/1.1" 200 466
2024-07-24 14:33:45,838 INFO django.utils.autoreload Watching for file changes with StatReloader
2024-07-24 14:33:45,838 INFO django.utils.autoreload Watching for file changes with StatReloader
2024-07-24 14:34:12,880 INFO django.utils.autoreload Watching for file changes with StatReloader
2024-07-24 14:34:12,880 INFO django.utils.autoreload Watching for file changes with StatReloader
2024-07-24 14:34:35,700 WARNING django.request Bad Request: /api/v1/reservations/book-room
2024-07-24 14:34:35,700 WARNING django.request Bad Request: /api/v1/reservations/book-room
2024-07-24 14:34:35,712 WARNING django.server "POST /api/v1/reservations/book-room HTTP/1.1" 400 74
2024-07-24 14:34:35,712 WARNING django.server "POST /api/v1/reservations/book-room HTTP/1.1" 400 74
2024-07-24 14:34:49,882 WARNING django.request Bad Request: /api/v1/reservations/book-room
2024-07-24 14:34:49,882 WARNING django.request Bad Request: /api/v1/reservations/book-room
2024-07-24 14:34:49,885 WARNING django.server "POST /api/v1/reservations/book-room HTTP/1.1" 400 65
2024-07-24 14:34:49,885 WARNING django.server "POST /api/v1/reservations/book-room HTTP/1.1" 400 65
2024-07-24 14:35:03,228 ERROR django.request Internal Server Error: /api/v1/reservations/checkout
Traceback (most recent call last):
  File "/home/kali/.local/lib/python3.11/site-packages/django/core/handlers/exception.py", line 55, in inner
    response = get_response(request)
               ^^^^^^^^^^^^^^^^^^^^^
  File "/home/kali/.local/lib/python3.11/site-packages/django/core/handlers/base.py", line 197, in _get_response
    response = wrapped_callback(request, *callback_args, **callback_kwargs)
               ^^^^^^^^^^^^^^^^^^^^^^^^^^^^^^^^^^^^^^^^^^^^^^^^^^^^^^^^^^^^
  File "/home/kali/.local/lib/python3.11/site-packages/django/views/decorators/csrf.py", line 65, in _view_wrapper
    return view_func(request, *args, **kwargs)
           ^^^^^^^^^^^^^^^^^^^^^^^^^^^^^^^^^^^
  File "/home/kali/.local/lib/python3.11/site-packages/django/views/generic/base.py", line 104, in view
    return self.dispatch(request, *args, **kwargs)
           ^^^^^^^^^^^^^^^^^^^^^^^^^^^^^^^^^^^^^^^
  File "/home/kali/.local/lib/python3.11/site-packages/rest_framework/views.py", line 509, in dispatch
    response = self.handle_exception(exc)
               ^^^^^^^^^^^^^^^^^^^^^^^^^^
  File "/home/kali/.local/lib/python3.11/site-packages/rest_framework/views.py", line 469, in handle_exception
    self.raise_uncaught_exception(exc)
  File "/home/kali/.local/lib/python3.11/site-packages/rest_framework/views.py", line 480, in raise_uncaught_exception
    raise exc
  File "/home/kali/.local/lib/python3.11/site-packages/rest_framework/views.py", line 506, in dispatch
    response = handler(request, *args, **kwargs)
               ^^^^^^^^^^^^^^^^^^^^^^^^^^^^^^^^^
  File "/home/kali/Desktop/ruumready/hotel_manager/reservations/views.py", line 426, in patch
    serializer.update(validated_data=request.data)
  File "/home/kali/Desktop/ruumready/hotel_manager/reservations/serializers.py", line 246, in update
    model = Booking.objects.check_user_out_ext(
            ^^^^^^^^^^^^^^^^^^^^^^^^^^^^^^^^^^^
  File "/home/kali/Desktop/ruumready/hotel_manager/reservations/managers.py", line 302, in check_user_out_ext
    booking_record = Booking.objects.filter(**{'id': record.booking.id})
                                                     ^^^^^^^^^^^^^^^^^
AttributeError: 'NoneType' object has no attribute 'id'
2024-07-24 14:35:03,228 ERROR django.request Internal Server Error: /api/v1/reservations/checkout
Traceback (most recent call last):
  File "/home/kali/.local/lib/python3.11/site-packages/django/core/handlers/exception.py", line 55, in inner
    response = get_response(request)
               ^^^^^^^^^^^^^^^^^^^^^
  File "/home/kali/.local/lib/python3.11/site-packages/django/core/handlers/base.py", line 197, in _get_response
    response = wrapped_callback(request, *callback_args, **callback_kwargs)
               ^^^^^^^^^^^^^^^^^^^^^^^^^^^^^^^^^^^^^^^^^^^^^^^^^^^^^^^^^^^^
  File "/home/kali/.local/lib/python3.11/site-packages/django/views/decorators/csrf.py", line 65, in _view_wrapper
    return view_func(request, *args, **kwargs)
           ^^^^^^^^^^^^^^^^^^^^^^^^^^^^^^^^^^^
  File "/home/kali/.local/lib/python3.11/site-packages/django/views/generic/base.py", line 104, in view
    return self.dispatch(request, *args, **kwargs)
           ^^^^^^^^^^^^^^^^^^^^^^^^^^^^^^^^^^^^^^^
  File "/home/kali/.local/lib/python3.11/site-packages/rest_framework/views.py", line 509, in dispatch
    response = self.handle_exception(exc)
               ^^^^^^^^^^^^^^^^^^^^^^^^^^
  File "/home/kali/.local/lib/python3.11/site-packages/rest_framework/views.py", line 469, in handle_exception
    self.raise_uncaught_exception(exc)
  File "/home/kali/.local/lib/python3.11/site-packages/rest_framework/views.py", line 480, in raise_uncaught_exception
    raise exc
  File "/home/kali/.local/lib/python3.11/site-packages/rest_framework/views.py", line 506, in dispatch
    response = handler(request, *args, **kwargs)
               ^^^^^^^^^^^^^^^^^^^^^^^^^^^^^^^^^
  File "/home/kali/Desktop/ruumready/hotel_manager/reservations/views.py", line 426, in patch
    serializer.update(validated_data=request.data)
  File "/home/kali/Desktop/ruumready/hotel_manager/reservations/serializers.py", line 246, in update
    model = Booking.objects.check_user_out_ext(
            ^^^^^^^^^^^^^^^^^^^^^^^^^^^^^^^^^^^
  File "/home/kali/Desktop/ruumready/hotel_manager/reservations/managers.py", line 302, in check_user_out_ext
    booking_record = Booking.objects.filter(**{'id': record.booking.id})
                                                     ^^^^^^^^^^^^^^^^^
AttributeError: 'NoneType' object has no attribute 'id'
2024-07-24 14:35:03,230 ERROR django.server "PATCH /api/v1/reservations/checkout HTTP/1.1" 500 112703
2024-07-24 14:35:03,230 ERROR django.server "PATCH /api/v1/reservations/checkout HTTP/1.1" 500 112703
2024-07-24 14:40:45,834 ERROR django.request Internal Server Error: /api/v1/reservations/checkout
Traceback (most recent call last):
  File "/home/kali/.local/lib/python3.11/site-packages/django/db/backends/base/base.py", line 275, in ensure_connection
    self.connect()
  File "/home/kali/.local/lib/python3.11/site-packages/django/utils/asyncio.py", line 26, in inner
    return func(*args, **kwargs)
           ^^^^^^^^^^^^^^^^^^^^^
  File "/home/kali/.local/lib/python3.11/site-packages/django/db/backends/base/base.py", line 256, in connect
    self.connection = self.get_new_connection(conn_params)
                      ^^^^^^^^^^^^^^^^^^^^^^^^^^^^^^^^^^^^
  File "/home/kali/.local/lib/python3.11/site-packages/django/utils/asyncio.py", line 26, in inner
    return func(*args, **kwargs)
           ^^^^^^^^^^^^^^^^^^^^^
  File "/home/kali/.local/lib/python3.11/site-packages/django/db/backends/postgresql/base.py", line 275, in get_new_connection
    connection = self.Database.connect(**conn_params)
                 ^^^^^^^^^^^^^^^^^^^^^^^^^^^^^^^^^^^^
  File "/usr/lib/python3/dist-packages/psycopg/connection.py", line 98, in connect
    attempts = conninfo_attempts(params)
               ^^^^^^^^^^^^^^^^^^^^^^^^^
  File "/usr/lib/python3/dist-packages/psycopg/_conninfo_attempts.py", line 50, in conninfo_attempts
    raise e.OperationalError(str(last_exc))
psycopg.OperationalError: [Errno -3] Temporary failure in name resolution

The above exception was the direct cause of the following exception:

Traceback (most recent call last):
  File "/home/kali/.local/lib/python3.11/site-packages/django/core/handlers/exception.py", line 55, in inner
    response = get_response(request)
               ^^^^^^^^^^^^^^^^^^^^^
  File "/home/kali/.local/lib/python3.11/site-packages/django/core/handlers/base.py", line 197, in _get_response
    response = wrapped_callback(request, *callback_args, **callback_kwargs)
               ^^^^^^^^^^^^^^^^^^^^^^^^^^^^^^^^^^^^^^^^^^^^^^^^^^^^^^^^^^^^
  File "/home/kali/.local/lib/python3.11/site-packages/django/views/decorators/csrf.py", line 65, in _view_wrapper
    return view_func(request, *args, **kwargs)
           ^^^^^^^^^^^^^^^^^^^^^^^^^^^^^^^^^^^
  File "/home/kali/.local/lib/python3.11/site-packages/django/views/generic/base.py", line 104, in view
    return self.dispatch(request, *args, **kwargs)
           ^^^^^^^^^^^^^^^^^^^^^^^^^^^^^^^^^^^^^^^
  File "/home/kali/.local/lib/python3.11/site-packages/rest_framework/views.py", line 509, in dispatch
    response = self.handle_exception(exc)
               ^^^^^^^^^^^^^^^^^^^^^^^^^^
  File "/home/kali/.local/lib/python3.11/site-packages/rest_framework/views.py", line 469, in handle_exception
    self.raise_uncaught_exception(exc)
  File "/home/kali/.local/lib/python3.11/site-packages/rest_framework/views.py", line 480, in raise_uncaught_exception
    raise exc
  File "/home/kali/.local/lib/python3.11/site-packages/rest_framework/views.py", line 506, in dispatch
    response = handler(request, *args, **kwargs)
               ^^^^^^^^^^^^^^^^^^^^^^^^^^^^^^^^^
  File "/home/kali/Desktop/ruumready/hotel_manager/reservations/views.py", line 426, in patch
    serializer.update(validated_data=request.data)
  File "/home/kali/Desktop/ruumready/hotel_manager/reservations/serializers.py", line 246, in update
    model = Booking.objects.check_user_out_ext(
            ^^^^^^^^^^^^^^^^^^^^^^^^^^^^^^^^^^^
  File "/home/kali/Desktop/ruumready/hotel_manager/reservations/managers.py", line 297, in check_user_out_ext
    if not record:
  File "/home/kali/.local/lib/python3.11/site-packages/django/db/models/query.py", line 412, in __bool__
    self._fetch_all()
  File "/home/kali/.local/lib/python3.11/site-packages/django/db/models/query.py", line 1926, in _fetch_all
    self._result_cache = list(self._iterable_class(self))
                         ^^^^^^^^^^^^^^^^^^^^^^^^^^^^^^^^
  File "/home/kali/.local/lib/python3.11/site-packages/django/db/models/query.py", line 91, in __iter__
    results = compiler.execute_sql(
              ^^^^^^^^^^^^^^^^^^^^^
  File "/home/kali/.local/lib/python3.11/site-packages/django/db/models/sql/compiler.py", line 1560, in execute_sql
    cursor = self.connection.cursor()
             ^^^^^^^^^^^^^^^^^^^^^^^^
  File "/home/kali/.local/lib/python3.11/site-packages/django/utils/asyncio.py", line 26, in inner
    return func(*args, **kwargs)
           ^^^^^^^^^^^^^^^^^^^^^
  File "/home/kali/.local/lib/python3.11/site-packages/django/db/backends/base/base.py", line 316, in cursor
    return self._cursor()
           ^^^^^^^^^^^^^^
  File "/home/kali/.local/lib/python3.11/site-packages/django/db/backends/base/base.py", line 292, in _cursor
    self.ensure_connection()
  File "/home/kali/.local/lib/python3.11/site-packages/django/utils/asyncio.py", line 26, in inner
    return func(*args, **kwargs)
           ^^^^^^^^^^^^^^^^^^^^^
  File "/home/kali/.local/lib/python3.11/site-packages/django/db/backends/base/base.py", line 274, in ensure_connection
    with self.wrap_database_errors:
  File "/home/kali/.local/lib/python3.11/site-packages/django/db/utils.py", line 91, in __exit__
    raise dj_exc_value.with_traceback(traceback) from exc_value
  File "/home/kali/.local/lib/python3.11/site-packages/django/db/backends/base/base.py", line 275, in ensure_connection
    self.connect()
  File "/home/kali/.local/lib/python3.11/site-packages/django/utils/asyncio.py", line 26, in inner
    return func(*args, **kwargs)
           ^^^^^^^^^^^^^^^^^^^^^
  File "/home/kali/.local/lib/python3.11/site-packages/django/db/backends/base/base.py", line 256, in connect
    self.connection = self.get_new_connection(conn_params)
                      ^^^^^^^^^^^^^^^^^^^^^^^^^^^^^^^^^^^^
  File "/home/kali/.local/lib/python3.11/site-packages/django/utils/asyncio.py", line 26, in inner
    return func(*args, **kwargs)
           ^^^^^^^^^^^^^^^^^^^^^
  File "/home/kali/.local/lib/python3.11/site-packages/django/db/backends/postgresql/base.py", line 275, in get_new_connection
    connection = self.Database.connect(**conn_params)
                 ^^^^^^^^^^^^^^^^^^^^^^^^^^^^^^^^^^^^
  File "/usr/lib/python3/dist-packages/psycopg/connection.py", line 98, in connect
    attempts = conninfo_attempts(params)
               ^^^^^^^^^^^^^^^^^^^^^^^^^
  File "/usr/lib/python3/dist-packages/psycopg/_conninfo_attempts.py", line 50, in conninfo_attempts
    raise e.OperationalError(str(last_exc))
django.db.utils.OperationalError: [Errno -3] Temporary failure in name resolution
2024-07-24 14:40:45,834 ERROR django.request Internal Server Error: /api/v1/reservations/checkout
Traceback (most recent call last):
  File "/home/kali/.local/lib/python3.11/site-packages/django/db/backends/base/base.py", line 275, in ensure_connection
    self.connect()
  File "/home/kali/.local/lib/python3.11/site-packages/django/utils/asyncio.py", line 26, in inner
    return func(*args, **kwargs)
           ^^^^^^^^^^^^^^^^^^^^^
  File "/home/kali/.local/lib/python3.11/site-packages/django/db/backends/base/base.py", line 256, in connect
    self.connection = self.get_new_connection(conn_params)
                      ^^^^^^^^^^^^^^^^^^^^^^^^^^^^^^^^^^^^
  File "/home/kali/.local/lib/python3.11/site-packages/django/utils/asyncio.py", line 26, in inner
    return func(*args, **kwargs)
           ^^^^^^^^^^^^^^^^^^^^^
  File "/home/kali/.local/lib/python3.11/site-packages/django/db/backends/postgresql/base.py", line 275, in get_new_connection
    connection = self.Database.connect(**conn_params)
                 ^^^^^^^^^^^^^^^^^^^^^^^^^^^^^^^^^^^^
  File "/usr/lib/python3/dist-packages/psycopg/connection.py", line 98, in connect
    attempts = conninfo_attempts(params)
               ^^^^^^^^^^^^^^^^^^^^^^^^^
  File "/usr/lib/python3/dist-packages/psycopg/_conninfo_attempts.py", line 50, in conninfo_attempts
    raise e.OperationalError(str(last_exc))
psycopg.OperationalError: [Errno -3] Temporary failure in name resolution

The above exception was the direct cause of the following exception:

Traceback (most recent call last):
  File "/home/kali/.local/lib/python3.11/site-packages/django/core/handlers/exception.py", line 55, in inner
    response = get_response(request)
               ^^^^^^^^^^^^^^^^^^^^^
  File "/home/kali/.local/lib/python3.11/site-packages/django/core/handlers/base.py", line 197, in _get_response
    response = wrapped_callback(request, *callback_args, **callback_kwargs)
               ^^^^^^^^^^^^^^^^^^^^^^^^^^^^^^^^^^^^^^^^^^^^^^^^^^^^^^^^^^^^
  File "/home/kali/.local/lib/python3.11/site-packages/django/views/decorators/csrf.py", line 65, in _view_wrapper
    return view_func(request, *args, **kwargs)
           ^^^^^^^^^^^^^^^^^^^^^^^^^^^^^^^^^^^
  File "/home/kali/.local/lib/python3.11/site-packages/django/views/generic/base.py", line 104, in view
    return self.dispatch(request, *args, **kwargs)
           ^^^^^^^^^^^^^^^^^^^^^^^^^^^^^^^^^^^^^^^
  File "/home/kali/.local/lib/python3.11/site-packages/rest_framework/views.py", line 509, in dispatch
    response = self.handle_exception(exc)
               ^^^^^^^^^^^^^^^^^^^^^^^^^^
  File "/home/kali/.local/lib/python3.11/site-packages/rest_framework/views.py", line 469, in handle_exception
    self.raise_uncaught_exception(exc)
  File "/home/kali/.local/lib/python3.11/site-packages/rest_framework/views.py", line 480, in raise_uncaught_exception
    raise exc
  File "/home/kali/.local/lib/python3.11/site-packages/rest_framework/views.py", line 506, in dispatch
    response = handler(request, *args, **kwargs)
               ^^^^^^^^^^^^^^^^^^^^^^^^^^^^^^^^^
  File "/home/kali/Desktop/ruumready/hotel_manager/reservations/views.py", line 426, in patch
    serializer.update(validated_data=request.data)
  File "/home/kali/Desktop/ruumready/hotel_manager/reservations/serializers.py", line 246, in update
    model = Booking.objects.check_user_out_ext(
            ^^^^^^^^^^^^^^^^^^^^^^^^^^^^^^^^^^^
  File "/home/kali/Desktop/ruumready/hotel_manager/reservations/managers.py", line 297, in check_user_out_ext
    if not record:
  File "/home/kali/.local/lib/python3.11/site-packages/django/db/models/query.py", line 412, in __bool__
    self._fetch_all()
  File "/home/kali/.local/lib/python3.11/site-packages/django/db/models/query.py", line 1926, in _fetch_all
    self._result_cache = list(self._iterable_class(self))
                         ^^^^^^^^^^^^^^^^^^^^^^^^^^^^^^^^
  File "/home/kali/.local/lib/python3.11/site-packages/django/db/models/query.py", line 91, in __iter__
    results = compiler.execute_sql(
              ^^^^^^^^^^^^^^^^^^^^^
  File "/home/kali/.local/lib/python3.11/site-packages/django/db/models/sql/compiler.py", line 1560, in execute_sql
    cursor = self.connection.cursor()
             ^^^^^^^^^^^^^^^^^^^^^^^^
  File "/home/kali/.local/lib/python3.11/site-packages/django/utils/asyncio.py", line 26, in inner
    return func(*args, **kwargs)
           ^^^^^^^^^^^^^^^^^^^^^
  File "/home/kali/.local/lib/python3.11/site-packages/django/db/backends/base/base.py", line 316, in cursor
    return self._cursor()
           ^^^^^^^^^^^^^^
  File "/home/kali/.local/lib/python3.11/site-packages/django/db/backends/base/base.py", line 292, in _cursor
    self.ensure_connection()
  File "/home/kali/.local/lib/python3.11/site-packages/django/utils/asyncio.py", line 26, in inner
    return func(*args, **kwargs)
           ^^^^^^^^^^^^^^^^^^^^^
  File "/home/kali/.local/lib/python3.11/site-packages/django/db/backends/base/base.py", line 274, in ensure_connection
    with self.wrap_database_errors:
  File "/home/kali/.local/lib/python3.11/site-packages/django/db/utils.py", line 91, in __exit__
    raise dj_exc_value.with_traceback(traceback) from exc_value
  File "/home/kali/.local/lib/python3.11/site-packages/django/db/backends/base/base.py", line 275, in ensure_connection
    self.connect()
  File "/home/kali/.local/lib/python3.11/site-packages/django/utils/asyncio.py", line 26, in inner
    return func(*args, **kwargs)
           ^^^^^^^^^^^^^^^^^^^^^
  File "/home/kali/.local/lib/python3.11/site-packages/django/db/backends/base/base.py", line 256, in connect
    self.connection = self.get_new_connection(conn_params)
                      ^^^^^^^^^^^^^^^^^^^^^^^^^^^^^^^^^^^^
  File "/home/kali/.local/lib/python3.11/site-packages/django/utils/asyncio.py", line 26, in inner
    return func(*args, **kwargs)
           ^^^^^^^^^^^^^^^^^^^^^
  File "/home/kali/.local/lib/python3.11/site-packages/django/db/backends/postgresql/base.py", line 275, in get_new_connection
    connection = self.Database.connect(**conn_params)
                 ^^^^^^^^^^^^^^^^^^^^^^^^^^^^^^^^^^^^
  File "/usr/lib/python3/dist-packages/psycopg/connection.py", line 98, in connect
    attempts = conninfo_attempts(params)
               ^^^^^^^^^^^^^^^^^^^^^^^^^
  File "/usr/lib/python3/dist-packages/psycopg/_conninfo_attempts.py", line 50, in conninfo_attempts
    raise e.OperationalError(str(last_exc))
django.db.utils.OperationalError: [Errno -3] Temporary failure in name resolution
2024-07-24 14:40:45,841 ERROR django.server "PATCH /api/v1/reservations/checkout HTTP/1.1" 500 223498
2024-07-24 14:40:45,841 ERROR django.server "PATCH /api/v1/reservations/checkout HTTP/1.1" 500 223498
2024-07-24 14:41:11,537 ERROR django.request Internal Server Error: /api/v1/reservations/book-room
Traceback (most recent call last):
  File "/home/kali/.local/lib/python3.11/site-packages/django/db/backends/base/base.py", line 275, in ensure_connection
    self.connect()
  File "/home/kali/.local/lib/python3.11/site-packages/django/utils/asyncio.py", line 26, in inner
    return func(*args, **kwargs)
           ^^^^^^^^^^^^^^^^^^^^^
  File "/home/kali/.local/lib/python3.11/site-packages/django/db/backends/base/base.py", line 256, in connect
    self.connection = self.get_new_connection(conn_params)
                      ^^^^^^^^^^^^^^^^^^^^^^^^^^^^^^^^^^^^
  File "/home/kali/.local/lib/python3.11/site-packages/django/utils/asyncio.py", line 26, in inner
    return func(*args, **kwargs)
           ^^^^^^^^^^^^^^^^^^^^^
  File "/home/kali/.local/lib/python3.11/site-packages/django/db/backends/postgresql/base.py", line 275, in get_new_connection
    connection = self.Database.connect(**conn_params)
                 ^^^^^^^^^^^^^^^^^^^^^^^^^^^^^^^^^^^^
  File "/usr/lib/python3/dist-packages/psycopg/connection.py", line 98, in connect
    attempts = conninfo_attempts(params)
               ^^^^^^^^^^^^^^^^^^^^^^^^^
  File "/usr/lib/python3/dist-packages/psycopg/_conninfo_attempts.py", line 50, in conninfo_attempts
    raise e.OperationalError(str(last_exc))
psycopg.OperationalError: [Errno -3] Temporary failure in name resolution

The above exception was the direct cause of the following exception:

Traceback (most recent call last):
  File "/home/kali/.local/lib/python3.11/site-packages/django/core/handlers/exception.py", line 55, in inner
    response = get_response(request)
               ^^^^^^^^^^^^^^^^^^^^^
  File "/home/kali/.local/lib/python3.11/site-packages/django/core/handlers/base.py", line 197, in _get_response
    response = wrapped_callback(request, *callback_args, **callback_kwargs)
               ^^^^^^^^^^^^^^^^^^^^^^^^^^^^^^^^^^^^^^^^^^^^^^^^^^^^^^^^^^^^
  File "/home/kali/.local/lib/python3.11/site-packages/django/views/decorators/csrf.py", line 65, in _view_wrapper
    return view_func(request, *args, **kwargs)
           ^^^^^^^^^^^^^^^^^^^^^^^^^^^^^^^^^^^
  File "/home/kali/.local/lib/python3.11/site-packages/django/views/generic/base.py", line 104, in view
    return self.dispatch(request, *args, **kwargs)
           ^^^^^^^^^^^^^^^^^^^^^^^^^^^^^^^^^^^^^^^
  File "/home/kali/.local/lib/python3.11/site-packages/rest_framework/views.py", line 509, in dispatch
    response = self.handle_exception(exc)
               ^^^^^^^^^^^^^^^^^^^^^^^^^^
  File "/home/kali/.local/lib/python3.11/site-packages/rest_framework/views.py", line 469, in handle_exception
    self.raise_uncaught_exception(exc)
  File "/home/kali/.local/lib/python3.11/site-packages/rest_framework/views.py", line 480, in raise_uncaught_exception
    raise exc
  File "/home/kali/.local/lib/python3.11/site-packages/rest_framework/views.py", line 506, in dispatch
    response = handler(request, *args, **kwargs)
               ^^^^^^^^^^^^^^^^^^^^^^^^^^^^^^^^^
  File "/home/kali/Desktop/ruumready/hotel_manager/reservations/views.py", line 254, in post
    serializer.save()
  File "/home/kali/.local/lib/python3.11/site-packages/rest_framework/serializers.py", line 212, in save
    self.instance = self.create(validated_data)
                    ^^^^^^^^^^^^^^^^^^^^^^^^^^^
  File "/home/kali/Desktop/ruumready/hotel_manager/reservations/serializers.py", line 203, in create
    booking = Booking.objects.create_booking_1(
              ^^^^^^^^^^^^^^^^^^^^^^^^^^^^^^^^^
  File "/home/kali/Desktop/ruumready/hotel_manager/reservations/managers.py", line 111, in create_booking_1
    if not room_allocation_instance:
  File "/home/kali/.local/lib/python3.11/site-packages/django/db/models/query.py", line 412, in __bool__
    self._fetch_all()
  File "/home/kali/.local/lib/python3.11/site-packages/django/db/models/query.py", line 1926, in _fetch_all
    self._result_cache = list(self._iterable_class(self))
                         ^^^^^^^^^^^^^^^^^^^^^^^^^^^^^^^^
  File "/home/kali/.local/lib/python3.11/site-packages/django/db/models/query.py", line 91, in __iter__
    results = compiler.execute_sql(
              ^^^^^^^^^^^^^^^^^^^^^
  File "/home/kali/.local/lib/python3.11/site-packages/django/db/models/sql/compiler.py", line 1560, in execute_sql
    cursor = self.connection.cursor()
             ^^^^^^^^^^^^^^^^^^^^^^^^
  File "/home/kali/.local/lib/python3.11/site-packages/django/utils/asyncio.py", line 26, in inner
    return func(*args, **kwargs)
           ^^^^^^^^^^^^^^^^^^^^^
  File "/home/kali/.local/lib/python3.11/site-packages/django/db/backends/base/base.py", line 316, in cursor
    return self._cursor()
           ^^^^^^^^^^^^^^
  File "/home/kali/.local/lib/python3.11/site-packages/django/db/backends/base/base.py", line 292, in _cursor
    self.ensure_connection()
  File "/home/kali/.local/lib/python3.11/site-packages/django/utils/asyncio.py", line 26, in inner
    return func(*args, **kwargs)
           ^^^^^^^^^^^^^^^^^^^^^
  File "/home/kali/.local/lib/python3.11/site-packages/django/db/backends/base/base.py", line 274, in ensure_connection
    with self.wrap_database_errors:
  File "/home/kali/.local/lib/python3.11/site-packages/django/db/utils.py", line 91, in __exit__
    raise dj_exc_value.with_traceback(traceback) from exc_value
  File "/home/kali/.local/lib/python3.11/site-packages/django/db/backends/base/base.py", line 275, in ensure_connection
    self.connect()
  File "/home/kali/.local/lib/python3.11/site-packages/django/utils/asyncio.py", line 26, in inner
    return func(*args, **kwargs)
           ^^^^^^^^^^^^^^^^^^^^^
  File "/home/kali/.local/lib/python3.11/site-packages/django/db/backends/base/base.py", line 256, in connect
    self.connection = self.get_new_connection(conn_params)
                      ^^^^^^^^^^^^^^^^^^^^^^^^^^^^^^^^^^^^
  File "/home/kali/.local/lib/python3.11/site-packages/django/utils/asyncio.py", line 26, in inner
    return func(*args, **kwargs)
           ^^^^^^^^^^^^^^^^^^^^^
  File "/home/kali/.local/lib/python3.11/site-packages/django/db/backends/postgresql/base.py", line 275, in get_new_connection
    connection = self.Database.connect(**conn_params)
                 ^^^^^^^^^^^^^^^^^^^^^^^^^^^^^^^^^^^^
  File "/usr/lib/python3/dist-packages/psycopg/connection.py", line 98, in connect
    attempts = conninfo_attempts(params)
               ^^^^^^^^^^^^^^^^^^^^^^^^^
  File "/usr/lib/python3/dist-packages/psycopg/_conninfo_attempts.py", line 50, in conninfo_attempts
    raise e.OperationalError(str(last_exc))
django.db.utils.OperationalError: [Errno -3] Temporary failure in name resolution
2024-07-24 14:41:11,537 ERROR django.request Internal Server Error: /api/v1/reservations/book-room
Traceback (most recent call last):
  File "/home/kali/.local/lib/python3.11/site-packages/django/db/backends/base/base.py", line 275, in ensure_connection
    self.connect()
  File "/home/kali/.local/lib/python3.11/site-packages/django/utils/asyncio.py", line 26, in inner
    return func(*args, **kwargs)
           ^^^^^^^^^^^^^^^^^^^^^
  File "/home/kali/.local/lib/python3.11/site-packages/django/db/backends/base/base.py", line 256, in connect
    self.connection = self.get_new_connection(conn_params)
                      ^^^^^^^^^^^^^^^^^^^^^^^^^^^^^^^^^^^^
  File "/home/kali/.local/lib/python3.11/site-packages/django/utils/asyncio.py", line 26, in inner
    return func(*args, **kwargs)
           ^^^^^^^^^^^^^^^^^^^^^
  File "/home/kali/.local/lib/python3.11/site-packages/django/db/backends/postgresql/base.py", line 275, in get_new_connection
    connection = self.Database.connect(**conn_params)
                 ^^^^^^^^^^^^^^^^^^^^^^^^^^^^^^^^^^^^
  File "/usr/lib/python3/dist-packages/psycopg/connection.py", line 98, in connect
    attempts = conninfo_attempts(params)
               ^^^^^^^^^^^^^^^^^^^^^^^^^
  File "/usr/lib/python3/dist-packages/psycopg/_conninfo_attempts.py", line 50, in conninfo_attempts
    raise e.OperationalError(str(last_exc))
psycopg.OperationalError: [Errno -3] Temporary failure in name resolution

The above exception was the direct cause of the following exception:

Traceback (most recent call last):
  File "/home/kali/.local/lib/python3.11/site-packages/django/core/handlers/exception.py", line 55, in inner
    response = get_response(request)
               ^^^^^^^^^^^^^^^^^^^^^
  File "/home/kali/.local/lib/python3.11/site-packages/django/core/handlers/base.py", line 197, in _get_response
    response = wrapped_callback(request, *callback_args, **callback_kwargs)
               ^^^^^^^^^^^^^^^^^^^^^^^^^^^^^^^^^^^^^^^^^^^^^^^^^^^^^^^^^^^^
  File "/home/kali/.local/lib/python3.11/site-packages/django/views/decorators/csrf.py", line 65, in _view_wrapper
    return view_func(request, *args, **kwargs)
           ^^^^^^^^^^^^^^^^^^^^^^^^^^^^^^^^^^^
  File "/home/kali/.local/lib/python3.11/site-packages/django/views/generic/base.py", line 104, in view
    return self.dispatch(request, *args, **kwargs)
           ^^^^^^^^^^^^^^^^^^^^^^^^^^^^^^^^^^^^^^^
  File "/home/kali/.local/lib/python3.11/site-packages/rest_framework/views.py", line 509, in dispatch
    response = self.handle_exception(exc)
               ^^^^^^^^^^^^^^^^^^^^^^^^^^
  File "/home/kali/.local/lib/python3.11/site-packages/rest_framework/views.py", line 469, in handle_exception
    self.raise_uncaught_exception(exc)
  File "/home/kali/.local/lib/python3.11/site-packages/rest_framework/views.py", line 480, in raise_uncaught_exception
    raise exc
  File "/home/kali/.local/lib/python3.11/site-packages/rest_framework/views.py", line 506, in dispatch
    response = handler(request, *args, **kwargs)
               ^^^^^^^^^^^^^^^^^^^^^^^^^^^^^^^^^
  File "/home/kali/Desktop/ruumready/hotel_manager/reservations/views.py", line 254, in post
    serializer.save()
  File "/home/kali/.local/lib/python3.11/site-packages/rest_framework/serializers.py", line 212, in save
    self.instance = self.create(validated_data)
                    ^^^^^^^^^^^^^^^^^^^^^^^^^^^
  File "/home/kali/Desktop/ruumready/hotel_manager/reservations/serializers.py", line 203, in create
    booking = Booking.objects.create_booking_1(
              ^^^^^^^^^^^^^^^^^^^^^^^^^^^^^^^^^
  File "/home/kali/Desktop/ruumready/hotel_manager/reservations/managers.py", line 111, in create_booking_1
    if not room_allocation_instance:
  File "/home/kali/.local/lib/python3.11/site-packages/django/db/models/query.py", line 412, in __bool__
    self._fetch_all()
  File "/home/kali/.local/lib/python3.11/site-packages/django/db/models/query.py", line 1926, in _fetch_all
    self._result_cache = list(self._iterable_class(self))
                         ^^^^^^^^^^^^^^^^^^^^^^^^^^^^^^^^
  File "/home/kali/.local/lib/python3.11/site-packages/django/db/models/query.py", line 91, in __iter__
    results = compiler.execute_sql(
              ^^^^^^^^^^^^^^^^^^^^^
  File "/home/kali/.local/lib/python3.11/site-packages/django/db/models/sql/compiler.py", line 1560, in execute_sql
    cursor = self.connection.cursor()
             ^^^^^^^^^^^^^^^^^^^^^^^^
  File "/home/kali/.local/lib/python3.11/site-packages/django/utils/asyncio.py", line 26, in inner
    return func(*args, **kwargs)
           ^^^^^^^^^^^^^^^^^^^^^
  File "/home/kali/.local/lib/python3.11/site-packages/django/db/backends/base/base.py", line 316, in cursor
    return self._cursor()
           ^^^^^^^^^^^^^^
  File "/home/kali/.local/lib/python3.11/site-packages/django/db/backends/base/base.py", line 292, in _cursor
    self.ensure_connection()
  File "/home/kali/.local/lib/python3.11/site-packages/django/utils/asyncio.py", line 26, in inner
    return func(*args, **kwargs)
           ^^^^^^^^^^^^^^^^^^^^^
  File "/home/kali/.local/lib/python3.11/site-packages/django/db/backends/base/base.py", line 274, in ensure_connection
    with self.wrap_database_errors:
  File "/home/kali/.local/lib/python3.11/site-packages/django/db/utils.py", line 91, in __exit__
    raise dj_exc_value.with_traceback(traceback) from exc_value
  File "/home/kali/.local/lib/python3.11/site-packages/django/db/backends/base/base.py", line 275, in ensure_connection
    self.connect()
  File "/home/kali/.local/lib/python3.11/site-packages/django/utils/asyncio.py", line 26, in inner
    return func(*args, **kwargs)
           ^^^^^^^^^^^^^^^^^^^^^
  File "/home/kali/.local/lib/python3.11/site-packages/django/db/backends/base/base.py", line 256, in connect
    self.connection = self.get_new_connection(conn_params)
                      ^^^^^^^^^^^^^^^^^^^^^^^^^^^^^^^^^^^^
  File "/home/kali/.local/lib/python3.11/site-packages/django/utils/asyncio.py", line 26, in inner
    return func(*args, **kwargs)
           ^^^^^^^^^^^^^^^^^^^^^
  File "/home/kali/.local/lib/python3.11/site-packages/django/db/backends/postgresql/base.py", line 275, in get_new_connection
    connection = self.Database.connect(**conn_params)
                 ^^^^^^^^^^^^^^^^^^^^^^^^^^^^^^^^^^^^
  File "/usr/lib/python3/dist-packages/psycopg/connection.py", line 98, in connect
    attempts = conninfo_attempts(params)
               ^^^^^^^^^^^^^^^^^^^^^^^^^
  File "/usr/lib/python3/dist-packages/psycopg/_conninfo_attempts.py", line 50, in conninfo_attempts
    raise e.OperationalError(str(last_exc))
django.db.utils.OperationalError: [Errno -3] Temporary failure in name resolution
2024-07-24 14:41:11,541 ERROR django.server "POST /api/v1/reservations/book-room HTTP/1.1" 500 229088
2024-07-24 14:41:11,541 ERROR django.server "POST /api/v1/reservations/book-room HTTP/1.1" 500 229088
2024-07-24 14:41:35,184 ERROR django.request Internal Server Error: /api/v1/reservations/user-booking-history/ecab5863-6124-46a9-ae0c-4a132a3bd1b5
Traceback (most recent call last):
  File "/home/kali/.local/lib/python3.11/site-packages/django/db/backends/base/base.py", line 275, in ensure_connection
    self.connect()
  File "/home/kali/.local/lib/python3.11/site-packages/django/utils/asyncio.py", line 26, in inner
    return func(*args, **kwargs)
           ^^^^^^^^^^^^^^^^^^^^^
  File "/home/kali/.local/lib/python3.11/site-packages/django/db/backends/base/base.py", line 256, in connect
    self.connection = self.get_new_connection(conn_params)
                      ^^^^^^^^^^^^^^^^^^^^^^^^^^^^^^^^^^^^
  File "/home/kali/.local/lib/python3.11/site-packages/django/utils/asyncio.py", line 26, in inner
    return func(*args, **kwargs)
           ^^^^^^^^^^^^^^^^^^^^^
  File "/home/kali/.local/lib/python3.11/site-packages/django/db/backends/postgresql/base.py", line 275, in get_new_connection
    connection = self.Database.connect(**conn_params)
                 ^^^^^^^^^^^^^^^^^^^^^^^^^^^^^^^^^^^^
  File "/usr/lib/python3/dist-packages/psycopg/connection.py", line 98, in connect
    attempts = conninfo_attempts(params)
               ^^^^^^^^^^^^^^^^^^^^^^^^^
  File "/usr/lib/python3/dist-packages/psycopg/_conninfo_attempts.py", line 50, in conninfo_attempts
    raise e.OperationalError(str(last_exc))
psycopg.OperationalError: [Errno -3] Temporary failure in name resolution

The above exception was the direct cause of the following exception:

Traceback (most recent call last):
  File "/home/kali/.local/lib/python3.11/site-packages/django/core/handlers/exception.py", line 55, in inner
    response = get_response(request)
               ^^^^^^^^^^^^^^^^^^^^^
  File "/home/kali/.local/lib/python3.11/site-packages/django/core/handlers/base.py", line 197, in _get_response
    response = wrapped_callback(request, *callback_args, **callback_kwargs)
               ^^^^^^^^^^^^^^^^^^^^^^^^^^^^^^^^^^^^^^^^^^^^^^^^^^^^^^^^^^^^
  File "/home/kali/.local/lib/python3.11/site-packages/django/views/decorators/csrf.py", line 65, in _view_wrapper
    return view_func(request, *args, **kwargs)
           ^^^^^^^^^^^^^^^^^^^^^^^^^^^^^^^^^^^
  File "/home/kali/.local/lib/python3.11/site-packages/django/views/generic/base.py", line 104, in view
    return self.dispatch(request, *args, **kwargs)
           ^^^^^^^^^^^^^^^^^^^^^^^^^^^^^^^^^^^^^^^
  File "/home/kali/.local/lib/python3.11/site-packages/rest_framework/views.py", line 509, in dispatch
    response = self.handle_exception(exc)
               ^^^^^^^^^^^^^^^^^^^^^^^^^^
  File "/home/kali/.local/lib/python3.11/site-packages/rest_framework/views.py", line 469, in handle_exception
    self.raise_uncaught_exception(exc)
  File "/home/kali/.local/lib/python3.11/site-packages/rest_framework/views.py", line 480, in raise_uncaught_exception
    raise exc
  File "/home/kali/.local/lib/python3.11/site-packages/rest_framework/views.py", line 506, in dispatch
    response = handler(request, *args, **kwargs)
               ^^^^^^^^^^^^^^^^^^^^^^^^^^^^^^^^^
  File "/home/kali/Desktop/ruumready/hotel_manager/reservations/views.py", line 199, in get
    queryset = Booking.objects.get_user_rooms_overview(user_id=user_id)
               ^^^^^^^^^^^^^^^^^^^^^^^^^^^^^^^^^^^^^^^^^^^^^^^^^^^^^^^^
  File "/home/kali/Desktop/ruumready/hotel_manager/reservations/managers.py", line 387, in get_user_rooms_overview
    if not records:
  File "/home/kali/.local/lib/python3.11/site-packages/django/db/models/query.py", line 412, in __bool__
    self._fetch_all()
  File "/home/kali/.local/lib/python3.11/site-packages/django/db/models/query.py", line 1926, in _fetch_all
    self._result_cache = list(self._iterable_class(self))
                         ^^^^^^^^^^^^^^^^^^^^^^^^^^^^^^^^
  File "/home/kali/.local/lib/python3.11/site-packages/django/db/models/query.py", line 91, in __iter__
    results = compiler.execute_sql(
              ^^^^^^^^^^^^^^^^^^^^^
  File "/home/kali/.local/lib/python3.11/site-packages/django/db/models/sql/compiler.py", line 1560, in execute_sql
    cursor = self.connection.cursor()
             ^^^^^^^^^^^^^^^^^^^^^^^^
  File "/home/kali/.local/lib/python3.11/site-packages/django/utils/asyncio.py", line 26, in inner
    return func(*args, **kwargs)
           ^^^^^^^^^^^^^^^^^^^^^
  File "/home/kali/.local/lib/python3.11/site-packages/django/db/backends/base/base.py", line 316, in cursor
    return self._cursor()
           ^^^^^^^^^^^^^^
  File "/home/kali/.local/lib/python3.11/site-packages/django/db/backends/base/base.py", line 292, in _cursor
    self.ensure_connection()
  File "/home/kali/.local/lib/python3.11/site-packages/django/utils/asyncio.py", line 26, in inner
    return func(*args, **kwargs)
           ^^^^^^^^^^^^^^^^^^^^^
  File "/home/kali/.local/lib/python3.11/site-packages/django/db/backends/base/base.py", line 274, in ensure_connection
    with self.wrap_database_errors:
  File "/home/kali/.local/lib/python3.11/site-packages/django/db/utils.py", line 91, in __exit__
    raise dj_exc_value.with_traceback(traceback) from exc_value
  File "/home/kali/.local/lib/python3.11/site-packages/django/db/backends/base/base.py", line 275, in ensure_connection
    self.connect()
  File "/home/kali/.local/lib/python3.11/site-packages/django/utils/asyncio.py", line 26, in inner
    return func(*args, **kwargs)
           ^^^^^^^^^^^^^^^^^^^^^
  File "/home/kali/.local/lib/python3.11/site-packages/django/db/backends/base/base.py", line 256, in connect
    self.connection = self.get_new_connection(conn_params)
                      ^^^^^^^^^^^^^^^^^^^^^^^^^^^^^^^^^^^^
  File "/home/kali/.local/lib/python3.11/site-packages/django/utils/asyncio.py", line 26, in inner
    return func(*args, **kwargs)
           ^^^^^^^^^^^^^^^^^^^^^
  File "/home/kali/.local/lib/python3.11/site-packages/django/db/backends/postgresql/base.py", line 275, in get_new_connection
    connection = self.Database.connect(**conn_params)
                 ^^^^^^^^^^^^^^^^^^^^^^^^^^^^^^^^^^^^
  File "/usr/lib/python3/dist-packages/psycopg/connection.py", line 98, in connect
    attempts = conninfo_attempts(params)
               ^^^^^^^^^^^^^^^^^^^^^^^^^
  File "/usr/lib/python3/dist-packages/psycopg/_conninfo_attempts.py", line 50, in conninfo_attempts
    raise e.OperationalError(str(last_exc))
django.db.utils.OperationalError: [Errno -3] Temporary failure in name resolution
2024-07-24 14:41:35,184 ERROR django.request Internal Server Error: /api/v1/reservations/user-booking-history/ecab5863-6124-46a9-ae0c-4a132a3bd1b5
Traceback (most recent call last):
  File "/home/kali/.local/lib/python3.11/site-packages/django/db/backends/base/base.py", line 275, in ensure_connection
    self.connect()
  File "/home/kali/.local/lib/python3.11/site-packages/django/utils/asyncio.py", line 26, in inner
    return func(*args, **kwargs)
           ^^^^^^^^^^^^^^^^^^^^^
  File "/home/kali/.local/lib/python3.11/site-packages/django/db/backends/base/base.py", line 256, in connect
    self.connection = self.get_new_connection(conn_params)
                      ^^^^^^^^^^^^^^^^^^^^^^^^^^^^^^^^^^^^
  File "/home/kali/.local/lib/python3.11/site-packages/django/utils/asyncio.py", line 26, in inner
    return func(*args, **kwargs)
           ^^^^^^^^^^^^^^^^^^^^^
  File "/home/kali/.local/lib/python3.11/site-packages/django/db/backends/postgresql/base.py", line 275, in get_new_connection
    connection = self.Database.connect(**conn_params)
                 ^^^^^^^^^^^^^^^^^^^^^^^^^^^^^^^^^^^^
  File "/usr/lib/python3/dist-packages/psycopg/connection.py", line 98, in connect
    attempts = conninfo_attempts(params)
               ^^^^^^^^^^^^^^^^^^^^^^^^^
  File "/usr/lib/python3/dist-packages/psycopg/_conninfo_attempts.py", line 50, in conninfo_attempts
    raise e.OperationalError(str(last_exc))
psycopg.OperationalError: [Errno -3] Temporary failure in name resolution

The above exception was the direct cause of the following exception:

Traceback (most recent call last):
  File "/home/kali/.local/lib/python3.11/site-packages/django/core/handlers/exception.py", line 55, in inner
    response = get_response(request)
               ^^^^^^^^^^^^^^^^^^^^^
  File "/home/kali/.local/lib/python3.11/site-packages/django/core/handlers/base.py", line 197, in _get_response
    response = wrapped_callback(request, *callback_args, **callback_kwargs)
               ^^^^^^^^^^^^^^^^^^^^^^^^^^^^^^^^^^^^^^^^^^^^^^^^^^^^^^^^^^^^
  File "/home/kali/.local/lib/python3.11/site-packages/django/views/decorators/csrf.py", line 65, in _view_wrapper
    return view_func(request, *args, **kwargs)
           ^^^^^^^^^^^^^^^^^^^^^^^^^^^^^^^^^^^
  File "/home/kali/.local/lib/python3.11/site-packages/django/views/generic/base.py", line 104, in view
    return self.dispatch(request, *args, **kwargs)
           ^^^^^^^^^^^^^^^^^^^^^^^^^^^^^^^^^^^^^^^
  File "/home/kali/.local/lib/python3.11/site-packages/rest_framework/views.py", line 509, in dispatch
    response = self.handle_exception(exc)
               ^^^^^^^^^^^^^^^^^^^^^^^^^^
  File "/home/kali/.local/lib/python3.11/site-packages/rest_framework/views.py", line 469, in handle_exception
    self.raise_uncaught_exception(exc)
  File "/home/kali/.local/lib/python3.11/site-packages/rest_framework/views.py", line 480, in raise_uncaught_exception
    raise exc
  File "/home/kali/.local/lib/python3.11/site-packages/rest_framework/views.py", line 506, in dispatch
    response = handler(request, *args, **kwargs)
               ^^^^^^^^^^^^^^^^^^^^^^^^^^^^^^^^^
  File "/home/kali/Desktop/ruumready/hotel_manager/reservations/views.py", line 199, in get
    queryset = Booking.objects.get_user_rooms_overview(user_id=user_id)
               ^^^^^^^^^^^^^^^^^^^^^^^^^^^^^^^^^^^^^^^^^^^^^^^^^^^^^^^^
  File "/home/kali/Desktop/ruumready/hotel_manager/reservations/managers.py", line 387, in get_user_rooms_overview
    if not records:
  File "/home/kali/.local/lib/python3.11/site-packages/django/db/models/query.py", line 412, in __bool__
    self._fetch_all()
  File "/home/kali/.local/lib/python3.11/site-packages/django/db/models/query.py", line 1926, in _fetch_all
    self._result_cache = list(self._iterable_class(self))
                         ^^^^^^^^^^^^^^^^^^^^^^^^^^^^^^^^
  File "/home/kali/.local/lib/python3.11/site-packages/django/db/models/query.py", line 91, in __iter__
    results = compiler.execute_sql(
              ^^^^^^^^^^^^^^^^^^^^^
  File "/home/kali/.local/lib/python3.11/site-packages/django/db/models/sql/compiler.py", line 1560, in execute_sql
    cursor = self.connection.cursor()
             ^^^^^^^^^^^^^^^^^^^^^^^^
  File "/home/kali/.local/lib/python3.11/site-packages/django/utils/asyncio.py", line 26, in inner
    return func(*args, **kwargs)
           ^^^^^^^^^^^^^^^^^^^^^
  File "/home/kali/.local/lib/python3.11/site-packages/django/db/backends/base/base.py", line 316, in cursor
    return self._cursor()
           ^^^^^^^^^^^^^^
  File "/home/kali/.local/lib/python3.11/site-packages/django/db/backends/base/base.py", line 292, in _cursor
    self.ensure_connection()
  File "/home/kali/.local/lib/python3.11/site-packages/django/utils/asyncio.py", line 26, in inner
    return func(*args, **kwargs)
           ^^^^^^^^^^^^^^^^^^^^^
  File "/home/kali/.local/lib/python3.11/site-packages/django/db/backends/base/base.py", line 274, in ensure_connection
    with self.wrap_database_errors:
  File "/home/kali/.local/lib/python3.11/site-packages/django/db/utils.py", line 91, in __exit__
    raise dj_exc_value.with_traceback(traceback) from exc_value
  File "/home/kali/.local/lib/python3.11/site-packages/django/db/backends/base/base.py", line 275, in ensure_connection
    self.connect()
  File "/home/kali/.local/lib/python3.11/site-packages/django/utils/asyncio.py", line 26, in inner
    return func(*args, **kwargs)
           ^^^^^^^^^^^^^^^^^^^^^
  File "/home/kali/.local/lib/python3.11/site-packages/django/db/backends/base/base.py", line 256, in connect
    self.connection = self.get_new_connection(conn_params)
                      ^^^^^^^^^^^^^^^^^^^^^^^^^^^^^^^^^^^^
  File "/home/kali/.local/lib/python3.11/site-packages/django/utils/asyncio.py", line 26, in inner
    return func(*args, **kwargs)
           ^^^^^^^^^^^^^^^^^^^^^
  File "/home/kali/.local/lib/python3.11/site-packages/django/db/backends/postgresql/base.py", line 275, in get_new_connection
    connection = self.Database.connect(**conn_params)
                 ^^^^^^^^^^^^^^^^^^^^^^^^^^^^^^^^^^^^
  File "/usr/lib/python3/dist-packages/psycopg/connection.py", line 98, in connect
    attempts = conninfo_attempts(params)
               ^^^^^^^^^^^^^^^^^^^^^^^^^
  File "/usr/lib/python3/dist-packages/psycopg/_conninfo_attempts.py", line 50, in conninfo_attempts
    raise e.OperationalError(str(last_exc))
django.db.utils.OperationalError: [Errno -3] Temporary failure in name resolution
2024-07-24 14:41:35,186 ERROR django.server "GET /api/v1/reservations/user-booking-history/ecab5863-6124-46a9-ae0c-4a132a3bd1b5 HTTP/1.1" 500 219499
2024-07-24 14:41:35,186 ERROR django.server "GET /api/v1/reservations/user-booking-history/ecab5863-6124-46a9-ae0c-4a132a3bd1b5 HTTP/1.1" 500 219499
2024-07-24 14:42:01,723 INFO django.utils.autoreload Watching for file changes with StatReloader
2024-07-24 14:42:01,723 INFO django.utils.autoreload Watching for file changes with StatReloader
2024-07-24 14:43:38,040 INFO django.utils.autoreload Watching for file changes with StatReloader
2024-07-24 14:43:38,040 INFO django.utils.autoreload Watching for file changes with StatReloader
2024-07-24 14:43:47,312 WARNING django.request Not Found: /api/v1/reservations/book-room
2024-07-24 14:43:47,312 WARNING django.request Not Found: /api/v1/reservations/book-room
2024-07-24 14:43:47,314 WARNING django.server "POST /api/v1/reservations/book-room HTTP/1.1" 404 65
2024-07-24 14:43:47,314 WARNING django.server "POST /api/v1/reservations/book-room HTTP/1.1" 404 65
2024-07-24 14:44:33,918 WARNING django.request Not Found: /api/v1/reservations/book-room
2024-07-24 14:44:33,918 WARNING django.request Not Found: /api/v1/reservations/book-room
2024-07-24 14:44:33,923 WARNING django.server "POST /api/v1/reservations/book-room HTTP/1.1" 404 65
2024-07-24 14:44:33,923 WARNING django.server "POST /api/v1/reservations/book-room HTTP/1.1" 404 65
2024-07-24 14:44:56,735 WARNING django.request Bad Request: /api/v1/reservations/checkout
2024-07-24 14:44:56,735 WARNING django.request Bad Request: /api/v1/reservations/checkout
2024-07-24 14:44:56,735 WARNING django.server "PATCH /api/v1/reservations/checkout HTTP/1.1" 400 57
2024-07-24 14:44:56,735 WARNING django.server "PATCH /api/v1/reservations/checkout HTTP/1.1" 400 57
2024-07-24 14:45:09,244 WARNING django.request Not Found: /api/v1/reservations/book-room
2024-07-24 14:45:09,244 WARNING django.request Not Found: /api/v1/reservations/book-room
2024-07-24 14:45:09,252 WARNING django.server "POST /api/v1/reservations/book-room HTTP/1.1" 404 65
2024-07-24 14:45:09,252 WARNING django.server "POST /api/v1/reservations/book-room HTTP/1.1" 404 65
2024-07-25 09:47:33,397 INFO django.utils.autoreload Watching for file changes with StatReloader
2024-07-25 09:47:33,397 INFO django.utils.autoreload Watching for file changes with StatReloader
2024-07-25 09:47:55,834 WARNING django.request Bad Request: /api/v1/reservations/multiple_rooms_check_in
2024-07-25 09:47:55,834 WARNING django.request Bad Request: /api/v1/reservations/multiple_rooms_check_in
2024-07-25 09:47:55,849 WARNING django.server "PATCH /api/v1/reservations/multiple_rooms_check_in HTTP/1.1" 400 86
2024-07-25 09:47:55,849 WARNING django.server "PATCH /api/v1/reservations/multiple_rooms_check_in HTTP/1.1" 400 86
2024-07-25 09:50:07,066 WARNING django.request Not Found: /api/v1/reservations/book-room
2024-07-25 09:50:07,066 WARNING django.request Not Found: /api/v1/reservations/book-room
2024-07-25 09:50:07,070 WARNING django.server "POST /api/v1/reservations/book-room HTTP/1.1" 404 65
2024-07-25 09:50:07,070 WARNING django.server "POST /api/v1/reservations/book-room HTTP/1.1" 404 65
2024-07-25 09:50:22,842 WARNING django.request Not Found: /api/v1/reservations/book-room
2024-07-25 09:50:22,842 WARNING django.request Not Found: /api/v1/reservations/book-room
2024-07-25 09:50:22,851 WARNING django.server "POST /api/v1/reservations/book-room HTTP/1.1" 404 65
2024-07-25 09:50:22,851 WARNING django.server "POST /api/v1/reservations/book-room HTTP/1.1" 404 65
2024-07-25 09:51:34,179 INFO django.server "POST /api/v1/reservations/book-room HTTP/1.1" 201 47
2024-07-25 09:51:34,179 INFO django.server "POST /api/v1/reservations/book-room HTTP/1.1" 201 47
2024-07-25 09:51:54,690 INFO django.server "PATCH /api/v1/reservations/multiple_rooms_check_in HTTP/1.1" 200 147
2024-07-25 09:51:54,690 INFO django.server "PATCH /api/v1/reservations/multiple_rooms_check_in HTTP/1.1" 200 147
2024-07-25 09:59:04,392 INFO django.utils.autoreload /home/kali/Desktop/ruumready/hotel_manager/reservations/views.py changed, reloading.
2024-07-25 09:59:04,392 INFO django.utils.autoreload /home/kali/Desktop/ruumready/hotel_manager/reservations/views.py changed, reloading.
2024-07-25 09:59:06,959 INFO django.utils.autoreload Watching for file changes with StatReloader
2024-07-25 09:59:06,959 INFO django.utils.autoreload Watching for file changes with StatReloader
2024-07-25 10:00:26,306 INFO django.utils.autoreload /home/kali/Desktop/ruumready/hotel_manager/reservations/views.py changed, reloading.
2024-07-25 10:00:26,306 INFO django.utils.autoreload /home/kali/Desktop/ruumready/hotel_manager/reservations/views.py changed, reloading.
2024-07-25 10:00:29,210 INFO django.utils.autoreload Watching for file changes with StatReloader
2024-07-25 10:00:29,210 INFO django.utils.autoreload Watching for file changes with StatReloader
2024-07-25 10:00:35,113 INFO django.utils.autoreload /home/kali/Desktop/ruumready/hotel_manager/reservations/views.py changed, reloading.
2024-07-25 10:00:35,113 INFO django.utils.autoreload /home/kali/Desktop/ruumready/hotel_manager/reservations/views.py changed, reloading.
2024-07-25 10:00:37,136 INFO django.utils.autoreload Watching for file changes with StatReloader
2024-07-25 10:00:37,136 INFO django.utils.autoreload Watching for file changes with StatReloader
2024-07-25 12:26:36,189 INFO django.utils.autoreload Watching for file changes with StatReloader
2024-07-25 12:26:36,189 INFO django.utils.autoreload Watching for file changes with StatReloader
2024-07-25 12:27:02,921 INFO django.utils.autoreload /home/kali/Desktop/ruumready/hotel_manager/reservations/views.py changed, reloading.
2024-07-25 12:27:02,921 INFO django.utils.autoreload /home/kali/Desktop/ruumready/hotel_manager/reservations/views.py changed, reloading.
2024-07-25 12:27:06,631 INFO django.utils.autoreload Watching for file changes with StatReloader
2024-07-25 12:27:06,631 INFO django.utils.autoreload Watching for file changes with StatReloader
2024-07-25 12:27:08,266 INFO django.utils.autoreload /home/kali/Desktop/ruumready/hotel_manager/reservations/views.py changed, reloading.
2024-07-25 12:27:08,266 INFO django.utils.autoreload /home/kali/Desktop/ruumready/hotel_manager/reservations/views.py changed, reloading.
2024-07-25 12:27:09,396 INFO django.utils.autoreload Watching for file changes with StatReloader
2024-07-25 12:27:09,396 INFO django.utils.autoreload Watching for file changes with StatReloader
2024-07-25 12:27:16,275 INFO django.utils.autoreload /home/kali/Desktop/ruumready/hotel_manager/reservations/views.py changed, reloading.
2024-07-25 12:27:16,275 INFO django.utils.autoreload /home/kali/Desktop/ruumready/hotel_manager/reservations/views.py changed, reloading.
2024-07-25 12:27:18,226 INFO django.utils.autoreload Watching for file changes with StatReloader
2024-07-25 12:27:18,226 INFO django.utils.autoreload Watching for file changes with StatReloader
2024-07-25 12:27:23,035 INFO django.utils.autoreload /home/kali/Desktop/ruumready/hotel_manager/reservations/views.py changed, reloading.
2024-07-25 12:27:23,035 INFO django.utils.autoreload /home/kali/Desktop/ruumready/hotel_manager/reservations/views.py changed, reloading.
2024-07-25 12:27:24,416 INFO django.utils.autoreload Watching for file changes with StatReloader
2024-07-25 12:27:24,416 INFO django.utils.autoreload Watching for file changes with StatReloader
2024-07-25 12:27:26,944 INFO django.utils.autoreload /home/kali/Desktop/ruumready/hotel_manager/reservations/views.py changed, reloading.
2024-07-25 12:27:26,944 INFO django.utils.autoreload /home/kali/Desktop/ruumready/hotel_manager/reservations/views.py changed, reloading.
2024-07-25 12:27:28,561 INFO django.utils.autoreload Watching for file changes with StatReloader
2024-07-25 12:27:28,561 INFO django.utils.autoreload Watching for file changes with StatReloader
2024-07-25 12:27:54,484 INFO django.utils.autoreload /home/kali/Desktop/ruumready/hotel_manager/reservations/managers.py changed, reloading.
2024-07-25 12:27:54,484 INFO django.utils.autoreload /home/kali/Desktop/ruumready/hotel_manager/reservations/managers.py changed, reloading.
2024-07-25 12:27:59,662 INFO django.utils.autoreload Watching for file changes with StatReloader
2024-07-25 12:27:59,662 INFO django.utils.autoreload Watching for file changes with StatReloader
2024-07-25 21:00:15,795 INFO django.utils.autoreload /home/kali/Desktop/ruumready/hotel_manager/reservations/managers.py changed, reloading.
2024-07-25 21:00:15,795 INFO django.utils.autoreload /home/kali/Desktop/ruumready/hotel_manager/reservations/managers.py changed, reloading.
2024-07-25 21:00:18,264 INFO django.utils.autoreload Watching for file changes with StatReloader
2024-07-25 21:00:18,264 INFO django.utils.autoreload Watching for file changes with StatReloader
2024-07-25 21:00:27,708 INFO django.utils.autoreload /home/kali/Desktop/ruumready/hotel_manager/reservations/managers.py changed, reloading.
2024-07-25 21:00:27,708 INFO django.utils.autoreload /home/kali/Desktop/ruumready/hotel_manager/reservations/managers.py changed, reloading.
2024-07-25 21:00:29,722 INFO django.utils.autoreload Watching for file changes with StatReloader
2024-07-25 21:00:29,722 INFO django.utils.autoreload Watching for file changes with StatReloader
2024-07-25 21:01:04,016 INFO django.utils.autoreload /home/kali/Desktop/ruumready/hotel_manager/reservations/views.py changed, reloading.
2024-07-25 21:01:04,016 INFO django.utils.autoreload /home/kali/Desktop/ruumready/hotel_manager/reservations/views.py changed, reloading.
2024-07-25 21:01:06,168 INFO django.utils.autoreload Watching for file changes with StatReloader
2024-07-25 21:01:06,168 INFO django.utils.autoreload Watching for file changes with StatReloader
2024-07-25 21:08:20,103 INFO django.utils.autoreload /home/kali/Desktop/ruumready/hotel_manager/reservations/views.py changed, reloading.
2024-07-25 21:08:20,103 INFO django.utils.autoreload /home/kali/Desktop/ruumready/hotel_manager/reservations/views.py changed, reloading.
2024-07-25 21:08:21,763 INFO django.utils.autoreload Watching for file changes with StatReloader
2024-07-25 21:08:21,763 INFO django.utils.autoreload Watching for file changes with StatReloader
2024-07-25 21:13:49,747 INFO django.utils.autoreload /home/kali/Desktop/ruumready/hotel_manager/reservations/views.py changed, reloading.
2024-07-25 21:13:49,747 INFO django.utils.autoreload /home/kali/Desktop/ruumready/hotel_manager/reservations/views.py changed, reloading.
2024-07-25 21:13:52,277 INFO django.utils.autoreload Watching for file changes with StatReloader
2024-07-25 21:13:52,277 INFO django.utils.autoreload Watching for file changes with StatReloader
2024-07-25 21:19:18,431 INFO django.utils.autoreload Watching for file changes with StatReloader
2024-07-25 21:19:18,431 INFO django.utils.autoreload Watching for file changes with StatReloader
2024-07-25 21:19:44,943 ERROR django.request Internal Server Error: /api/v1/reservations/checkout
Traceback (most recent call last):
  File "/home/kali/.local/lib/python3.11/site-packages/django/core/handlers/exception.py", line 55, in inner
    response = get_response(request)
               ^^^^^^^^^^^^^^^^^^^^^
  File "/home/kali/.local/lib/python3.11/site-packages/django/core/handlers/base.py", line 197, in _get_response
    response = wrapped_callback(request, *callback_args, **callback_kwargs)
               ^^^^^^^^^^^^^^^^^^^^^^^^^^^^^^^^^^^^^^^^^^^^^^^^^^^^^^^^^^^^
  File "/home/kali/.local/lib/python3.11/site-packages/django/views/decorators/csrf.py", line 65, in _view_wrapper
    return view_func(request, *args, **kwargs)
           ^^^^^^^^^^^^^^^^^^^^^^^^^^^^^^^^^^^
  File "/home/kali/.local/lib/python3.11/site-packages/django/views/generic/base.py", line 104, in view
    return self.dispatch(request, *args, **kwargs)
           ^^^^^^^^^^^^^^^^^^^^^^^^^^^^^^^^^^^^^^^
  File "/home/kali/.local/lib/python3.11/site-packages/rest_framework/views.py", line 509, in dispatch
    response = self.handle_exception(exc)
               ^^^^^^^^^^^^^^^^^^^^^^^^^^
  File "/home/kali/.local/lib/python3.11/site-packages/rest_framework/views.py", line 469, in handle_exception
    self.raise_uncaught_exception(exc)
  File "/home/kali/.local/lib/python3.11/site-packages/rest_framework/views.py", line 480, in raise_uncaught_exception
    raise exc
  File "/home/kali/.local/lib/python3.11/site-packages/rest_framework/views.py", line 506, in dispatch
    response = handler(request, *args, **kwargs)
               ^^^^^^^^^^^^^^^^^^^^^^^^^^^^^^^^^
  File "/home/kali/Desktop/ruumready/hotel_manager/reservations/views.py", line 425, in patch
    checked_out_rooms = serializer.update(validated_data=request.data)
                        ^^^^^^^^^^^^^^^^^^^^^^^^^^^^^^^^^^^^^^^^^^^^^^
  File "/home/kali/Desktop/ruumready/hotel_manager/reservations/serializers.py", line 246, in update
    model = Booking.objects.check_user_out_ext(
            ^^^^^^^^^^^^^^^^^^^^^^^^^^^^^^^^^^^
  File "/home/kali/Desktop/ruumready/hotel_manager/reservations/managers.py", line 317, in check_user_out_ext
    'room_name': record.room_name,  # Assuming RoomAllocation has room_name field
                 ^^^^^^^^^^^^^^^^
AttributeError: 'RoomAllocation' object has no attribute 'room_name'
2024-07-25 21:19:44,943 ERROR django.request Internal Server Error: /api/v1/reservations/checkout
Traceback (most recent call last):
  File "/home/kali/.local/lib/python3.11/site-packages/django/core/handlers/exception.py", line 55, in inner
    response = get_response(request)
               ^^^^^^^^^^^^^^^^^^^^^
  File "/home/kali/.local/lib/python3.11/site-packages/django/core/handlers/base.py", line 197, in _get_response
    response = wrapped_callback(request, *callback_args, **callback_kwargs)
               ^^^^^^^^^^^^^^^^^^^^^^^^^^^^^^^^^^^^^^^^^^^^^^^^^^^^^^^^^^^^
  File "/home/kali/.local/lib/python3.11/site-packages/django/views/decorators/csrf.py", line 65, in _view_wrapper
    return view_func(request, *args, **kwargs)
           ^^^^^^^^^^^^^^^^^^^^^^^^^^^^^^^^^^^
  File "/home/kali/.local/lib/python3.11/site-packages/django/views/generic/base.py", line 104, in view
    return self.dispatch(request, *args, **kwargs)
           ^^^^^^^^^^^^^^^^^^^^^^^^^^^^^^^^^^^^^^^
  File "/home/kali/.local/lib/python3.11/site-packages/rest_framework/views.py", line 509, in dispatch
    response = self.handle_exception(exc)
               ^^^^^^^^^^^^^^^^^^^^^^^^^^
  File "/home/kali/.local/lib/python3.11/site-packages/rest_framework/views.py", line 469, in handle_exception
    self.raise_uncaught_exception(exc)
  File "/home/kali/.local/lib/python3.11/site-packages/rest_framework/views.py", line 480, in raise_uncaught_exception
    raise exc
  File "/home/kali/.local/lib/python3.11/site-packages/rest_framework/views.py", line 506, in dispatch
    response = handler(request, *args, **kwargs)
               ^^^^^^^^^^^^^^^^^^^^^^^^^^^^^^^^^
  File "/home/kali/Desktop/ruumready/hotel_manager/reservations/views.py", line 425, in patch
    checked_out_rooms = serializer.update(validated_data=request.data)
                        ^^^^^^^^^^^^^^^^^^^^^^^^^^^^^^^^^^^^^^^^^^^^^^
  File "/home/kali/Desktop/ruumready/hotel_manager/reservations/serializers.py", line 246, in update
    model = Booking.objects.check_user_out_ext(
            ^^^^^^^^^^^^^^^^^^^^^^^^^^^^^^^^^^^
  File "/home/kali/Desktop/ruumready/hotel_manager/reservations/managers.py", line 317, in check_user_out_ext
    'room_name': record.room_name,  # Assuming RoomAllocation has room_name field
                 ^^^^^^^^^^^^^^^^
AttributeError: 'RoomAllocation' object has no attribute 'room_name'
2024-07-25 21:19:44,947 ERROR django.server "PATCH /api/v1/reservations/checkout HTTP/1.1" 500 112908
2024-07-25 21:19:44,947 ERROR django.server "PATCH /api/v1/reservations/checkout HTTP/1.1" 500 112908
2024-07-25 21:20:25,784 INFO django.utils.autoreload /home/kali/Desktop/ruumready/hotel_manager/reservations/managers.py changed, reloading.
2024-07-25 21:20:25,784 INFO django.utils.autoreload /home/kali/Desktop/ruumready/hotel_manager/reservations/managers.py changed, reloading.
2024-07-25 21:20:28,905 INFO django.utils.autoreload Watching for file changes with StatReloader
2024-07-25 21:20:28,905 INFO django.utils.autoreload Watching for file changes with StatReloader
2024-07-25 21:20:45,888 ERROR django.request Internal Server Error: /api/v1/reservations/checkout
Traceback (most recent call last):
  File "/home/kali/.local/lib/python3.11/site-packages/django/core/handlers/exception.py", line 55, in inner
    response = get_response(request)
               ^^^^^^^^^^^^^^^^^^^^^
  File "/home/kali/.local/lib/python3.11/site-packages/django/core/handlers/base.py", line 197, in _get_response
    response = wrapped_callback(request, *callback_args, **callback_kwargs)
               ^^^^^^^^^^^^^^^^^^^^^^^^^^^^^^^^^^^^^^^^^^^^^^^^^^^^^^^^^^^^
  File "/home/kali/.local/lib/python3.11/site-packages/django/views/decorators/csrf.py", line 65, in _view_wrapper
    return view_func(request, *args, **kwargs)
           ^^^^^^^^^^^^^^^^^^^^^^^^^^^^^^^^^^^
  File "/home/kali/.local/lib/python3.11/site-packages/django/views/generic/base.py", line 104, in view
    return self.dispatch(request, *args, **kwargs)
           ^^^^^^^^^^^^^^^^^^^^^^^^^^^^^^^^^^^^^^^
  File "/home/kali/.local/lib/python3.11/site-packages/rest_framework/views.py", line 509, in dispatch
    response = self.handle_exception(exc)
               ^^^^^^^^^^^^^^^^^^^^^^^^^^
  File "/home/kali/.local/lib/python3.11/site-packages/rest_framework/views.py", line 469, in handle_exception
    self.raise_uncaught_exception(exc)
  File "/home/kali/.local/lib/python3.11/site-packages/rest_framework/views.py", line 480, in raise_uncaught_exception
    raise exc
  File "/home/kali/.local/lib/python3.11/site-packages/rest_framework/views.py", line 506, in dispatch
    response = handler(request, *args, **kwargs)
               ^^^^^^^^^^^^^^^^^^^^^^^^^^^^^^^^^
  File "/home/kali/Desktop/ruumready/hotel_manager/reservations/views.py", line 425, in patch
    checked_out_rooms = serializer.update(validated_data=request.data)
                        ^^^^^^^^^^^^^^^^^^^^^^^^^^^^^^^^^^^^^^^^^^^^^^
  File "/home/kali/Desktop/ruumready/hotel_manager/reservations/serializers.py", line 246, in update
    model = Booking.objects.check_user_out_ext(
            ^^^^^^^^^^^^^^^^^^^^^^^^^^^^^^^^^^^
  File "/home/kali/Desktop/ruumready/hotel_manager/reservations/managers.py", line 300, in check_user_out_ext
    booking_record = Booking.objects.filter(**{'id': record.booking.id})
                                                     ^^^^^^^^^^^^^^^^^
AttributeError: 'NoneType' object has no attribute 'id'
2024-07-25 21:20:45,888 ERROR django.request Internal Server Error: /api/v1/reservations/checkout
Traceback (most recent call last):
  File "/home/kali/.local/lib/python3.11/site-packages/django/core/handlers/exception.py", line 55, in inner
    response = get_response(request)
               ^^^^^^^^^^^^^^^^^^^^^
  File "/home/kali/.local/lib/python3.11/site-packages/django/core/handlers/base.py", line 197, in _get_response
    response = wrapped_callback(request, *callback_args, **callback_kwargs)
               ^^^^^^^^^^^^^^^^^^^^^^^^^^^^^^^^^^^^^^^^^^^^^^^^^^^^^^^^^^^^
  File "/home/kali/.local/lib/python3.11/site-packages/django/views/decorators/csrf.py", line 65, in _view_wrapper
    return view_func(request, *args, **kwargs)
           ^^^^^^^^^^^^^^^^^^^^^^^^^^^^^^^^^^^
  File "/home/kali/.local/lib/python3.11/site-packages/django/views/generic/base.py", line 104, in view
    return self.dispatch(request, *args, **kwargs)
           ^^^^^^^^^^^^^^^^^^^^^^^^^^^^^^^^^^^^^^^
  File "/home/kali/.local/lib/python3.11/site-packages/rest_framework/views.py", line 509, in dispatch
    response = self.handle_exception(exc)
               ^^^^^^^^^^^^^^^^^^^^^^^^^^
  File "/home/kali/.local/lib/python3.11/site-packages/rest_framework/views.py", line 469, in handle_exception
    self.raise_uncaught_exception(exc)
  File "/home/kali/.local/lib/python3.11/site-packages/rest_framework/views.py", line 480, in raise_uncaught_exception
    raise exc
  File "/home/kali/.local/lib/python3.11/site-packages/rest_framework/views.py", line 506, in dispatch
    response = handler(request, *args, **kwargs)
               ^^^^^^^^^^^^^^^^^^^^^^^^^^^^^^^^^
  File "/home/kali/Desktop/ruumready/hotel_manager/reservations/views.py", line 425, in patch
    checked_out_rooms = serializer.update(validated_data=request.data)
                        ^^^^^^^^^^^^^^^^^^^^^^^^^^^^^^^^^^^^^^^^^^^^^^
  File "/home/kali/Desktop/ruumready/hotel_manager/reservations/serializers.py", line 246, in update
    model = Booking.objects.check_user_out_ext(
            ^^^^^^^^^^^^^^^^^^^^^^^^^^^^^^^^^^^
  File "/home/kali/Desktop/ruumready/hotel_manager/reservations/managers.py", line 300, in check_user_out_ext
    booking_record = Booking.objects.filter(**{'id': record.booking.id})
                                                     ^^^^^^^^^^^^^^^^^
AttributeError: 'NoneType' object has no attribute 'id'
2024-07-25 21:20:45,892 ERROR django.server "PATCH /api/v1/reservations/checkout HTTP/1.1" 500 112737
2024-07-25 21:20:45,892 ERROR django.server "PATCH /api/v1/reservations/checkout HTTP/1.1" 500 112737
2024-07-25 21:21:09,014 INFO django.utils.autoreload /home/kali/Desktop/ruumready/hotel_manager/reservations/managers.py changed, reloading.
2024-07-25 21:21:09,014 INFO django.utils.autoreload /home/kali/Desktop/ruumready/hotel_manager/reservations/managers.py changed, reloading.
2024-07-25 21:21:10,444 INFO django.utils.autoreload Watching for file changes with StatReloader
2024-07-25 21:21:10,444 INFO django.utils.autoreload Watching for file changes with StatReloader
2024-07-25 21:21:12,004 INFO django.utils.autoreload /home/kali/Desktop/ruumready/hotel_manager/reservations/managers.py changed, reloading.
2024-07-25 21:21:12,004 INFO django.utils.autoreload /home/kali/Desktop/ruumready/hotel_manager/reservations/managers.py changed, reloading.
2024-07-25 21:21:14,846 INFO django.utils.autoreload Watching for file changes with StatReloader
2024-07-25 21:21:14,846 INFO django.utils.autoreload Watching for file changes with StatReloader
2024-07-25 21:21:48,419 INFO django.utils.autoreload /home/kali/Desktop/ruumready/hotel_manager/reservations/managers.py changed, reloading.
2024-07-25 21:21:48,419 INFO django.utils.autoreload /home/kali/Desktop/ruumready/hotel_manager/reservations/managers.py changed, reloading.
2024-07-25 21:21:51,352 INFO django.utils.autoreload Watching for file changes with StatReloader
2024-07-25 21:21:51,352 INFO django.utils.autoreload Watching for file changes with StatReloader
2024-07-25 21:21:53,684 INFO django.utils.autoreload /home/kali/Desktop/ruumready/hotel_manager/reservations/managers.py changed, reloading.
2024-07-25 21:21:53,684 INFO django.utils.autoreload /home/kali/Desktop/ruumready/hotel_manager/reservations/managers.py changed, reloading.
2024-07-25 21:21:56,050 INFO django.utils.autoreload Watching for file changes with StatReloader
2024-07-25 21:21:56,050 INFO django.utils.autoreload Watching for file changes with StatReloader
2024-07-25 21:22:02,042 INFO django.utils.autoreload /home/kali/Desktop/ruumready/hotel_manager/reservations/managers.py changed, reloading.
2024-07-25 21:22:02,042 INFO django.utils.autoreload /home/kali/Desktop/ruumready/hotel_manager/reservations/managers.py changed, reloading.
2024-07-25 21:22:04,231 INFO django.utils.autoreload Watching for file changes with StatReloader
2024-07-25 21:22:04,231 INFO django.utils.autoreload Watching for file changes with StatReloader
2024-07-25 21:22:12,327 INFO django.utils.autoreload /home/kali/Desktop/ruumready/hotel_manager/reservations/managers.py changed, reloading.
2024-07-25 21:22:12,327 INFO django.utils.autoreload /home/kali/Desktop/ruumready/hotel_manager/reservations/managers.py changed, reloading.
2024-07-25 21:22:14,201 INFO django.utils.autoreload Watching for file changes with StatReloader
2024-07-25 21:22:14,201 INFO django.utils.autoreload Watching for file changes with StatReloader
2024-07-25 21:22:58,013 ERROR django.request Internal Server Error: /api/v1/reservations/checkout
Traceback (most recent call last):
  File "/home/kali/.local/lib/python3.11/site-packages/django/core/handlers/exception.py", line 55, in inner
    response = get_response(request)
               ^^^^^^^^^^^^^^^^^^^^^
  File "/home/kali/.local/lib/python3.11/site-packages/django/core/handlers/base.py", line 197, in _get_response
    response = wrapped_callback(request, *callback_args, **callback_kwargs)
               ^^^^^^^^^^^^^^^^^^^^^^^^^^^^^^^^^^^^^^^^^^^^^^^^^^^^^^^^^^^^
  File "/home/kali/.local/lib/python3.11/site-packages/django/views/decorators/csrf.py", line 65, in _view_wrapper
    return view_func(request, *args, **kwargs)
           ^^^^^^^^^^^^^^^^^^^^^^^^^^^^^^^^^^^
  File "/home/kali/.local/lib/python3.11/site-packages/django/views/generic/base.py", line 104, in view
    return self.dispatch(request, *args, **kwargs)
           ^^^^^^^^^^^^^^^^^^^^^^^^^^^^^^^^^^^^^^^
  File "/home/kali/.local/lib/python3.11/site-packages/rest_framework/views.py", line 509, in dispatch
    response = self.handle_exception(exc)
               ^^^^^^^^^^^^^^^^^^^^^^^^^^
  File "/home/kali/.local/lib/python3.11/site-packages/rest_framework/views.py", line 469, in handle_exception
    self.raise_uncaught_exception(exc)
  File "/home/kali/.local/lib/python3.11/site-packages/rest_framework/views.py", line 480, in raise_uncaught_exception
    raise exc
  File "/home/kali/.local/lib/python3.11/site-packages/rest_framework/views.py", line 506, in dispatch
    response = handler(request, *args, **kwargs)
               ^^^^^^^^^^^^^^^^^^^^^^^^^^^^^^^^^
  File "/home/kali/Desktop/ruumready/hotel_manager/reservations/views.py", line 425, in patch
    checked_out_rooms = serializer.update(validated_data=request.data)
                        ^^^^^^^^^^^^^^^^^^^^^^^^^^^^^^^^^^^^^^^^^^^^^^
  File "/home/kali/Desktop/ruumready/hotel_manager/reservations/serializers.py", line 246, in update
    model = Booking.objects.check_user_out_ext(
            ^^^^^^^^^^^^^^^^^^^^^^^^^^^^^^^^^^^
  File "/home/kali/Desktop/ruumready/hotel_manager/reservations/managers.py", line 309, in check_user_out_ext
    booking_record = Booking.objects.filter(**{'id': record.booking.id})
                                                     ^^^^^^^^^^^^^^^^^
AttributeError: 'NoneType' object has no attribute 'id'
